Workbook

Sheet PeakMem
A1: Reduction
C2: Reduction: needTS&Valid | G2: Reduction: needTS&Invalid | K2: Reduction: needTS&all | P2: Feasible region expansion
A3: mbv2 | C3: avg | D3: min | E3: max | G3: avg | H3: min | I3: max | K3: avg | L3: min | M3: max | S3: %
A4: vm96 | B4: DupNAS | C4: ='reduction_dist.'!I2 -> 64.456017 | D4: ='reduction_dist.'!J2 -> 20 | E4: ='reduction_dist.'!K2 -> 88.84 | G4: ='reduction_dist.'!I3 -> 41.221812 | H4: ='reduction_dist.'!J3 -> 0 | I4: ='reduction_dist.'!K3 -> 88 | K4: ='reduction_dist.'!I4 -> 57.824224 | L4: ='reduction_dist.'!J4 -> 0 | M4: ='reduction_dist.'!K4 -> 88.84 | O4: vm96 | P4: before TS valids | Q4: 0.2084 | R4: DupNAS | S4: 0.5656
B5: TinyTS | C5: ='reduction_dist.'!I5 -> 45.349414 | D5: ='reduction_dist.'!J5 -> 29.46 | E5: ='reduction_dist.'!K5 -> 47.75 | G5: ='reduction_dist.'!I6 -> 46.396094 | H5: ='reduction_dist.'!J6 -> 29.51 | I5: ='reduction_dist.'!K6 -> 48.44 | K5: ='reduction_dist.'!I7 -> 46.212625 | L5: ='reduction_dist.'!J7 -> 29.46 | M5: ='reduction_dist.'!K7 -> 48.44 | P5: before TS invalids | Q5: 0.7916 | R5: TinyTS | S5: 0.1388
B6: PatchTS | C6: ='reduction_dist.'!I8 -> 42.254904 | D6: ='reduction_dist.'!J8 -> 23.53 | E6: ='reduction_dist.'!K8 -> 80.81 | G6: ='reduction_dist.'!I9 -> 10.81391 | H6: ='reduction_dist.'!J9 -> 0 | I6: ='reduction_dist.'!K9 -> 85.23 | K6: ='reduction_dist.'!I10 -> 13.39572 | L6: ='reduction_dist.'!J10 -> 0 | M6: ='reduction_dist.'!K10 -> 85.23 | R6: PatchTS | S6: 0.065
A7: vm128 | B7: DupNAS | C7: ='reduction_dist.'!I11 -> 63.441149 | D7: ='reduction_dist.'!J11 -> 19.86 | E7: ='reduction_dist.'!K11 -> 88 | G7: ='reduction_dist.'!I12 -> 59.8814 | H7: ='reduction_dist.'!J12 -> 0 | I7: ='reduction_dist.'!K12 -> 88 | K7: ='reduction_dist.'!I13 -> 62.74235 | L7: ='reduction_dist.'!J13 -> 0 | M7: ='reduction_dist.'!K13 -> 88 | O7: vm128 | P7: before TS valids | Q7: 0.2725 | R7: DupNAS | S7: 0.5847
B8: TinyTS | C8: ='reduction_dist.'!I14 -> 46.648776 | D8: ='reduction_dist.'!J14 -> 41.61 | E8: ='reduction_dist.'!K14 -> 48.39 | G8: ='reduction_dist.'!I15 -> 46.325545 | H8: ='reduction_dist.'!J15 -> 29.51 | I8: ='reduction_dist.'!K15 -> 48.44 | K8: ='reduction_dist.'!I16 -> 46.400382 | L8: ='reduction_dist.'!J16 -> 29.51 | M8: ='reduction_dist.'!K16 -> 48.44 | P8: before TS invalids | Q8: 0.7275 | R8: TinyTS | S8: 0.1684
B9: PatchTS | C9: ='reduction_dist.'!I17 -> 45.593644 | D9: ='reduction_dist.'!J17 -> 19.86 | E9: ='reduction_dist.'!K17 -> 85.23 | G9: ='reduction_dist.'!I18 -> 9.5938802 | H9: ='reduction_dist.'!J18 -> 0 | I9: ='reduction_dist.'!K18 -> 81.06 | K9: ='reduction_dist.'!I19 -> 13.073239 | L9: ='reduction_dist.'!J19 -> 0 | M9: ='reduction_dist.'!K19 -> 85.23 | R9: PatchTS | S9: 0.0703
A10: vm256 | B10: DupNAS | C10: ='reduction_dist.'!I20 -> 56.224033 | D10: ='reduction_dist.'!J20 -> 1.32 | E10: ='reduction_dist.'!K20 -> 86.33 | G10: ='reduction_dist.'!I21 -> 75.735678 | H10: ='reduction_dist.'!J21 -> 40 | I10: ='reduction_dist.'!K21 -> 88 | K10: ='reduction_dist.'!I22 -> 57.519685 | L10: ='reduction_dist.'!J22 -> 1.32 | M10: ='reduction_dist.'!K22 -> 88 | O10: vm256 | P10: before TS valids | Q10: 0.4447 | R10: DupNAS | S10: 0.5184
B11: TinyTS | C11: ='reduction_dist.'!I23 -> 46.591585 | D11: ='reduction_dist.'!J23 -> 32.82 | E11: ='reduction_dist.'!K23 -> 48.42 | G11: ='reduction_dist.'!I24 -> 46.35514 | H11: ='reduction_dist.'!J24 -> 29.54 | I11: ='reduction_dist.'!K24 -> 48.44 | K11: ='reduction_dist.'!I25 -> 46.4391 | L11: ='reduction_dist.'!J25 -> 29.54 | M11: ='reduction_dist.'!K25 -> 48.44 | P11: before TS invalids | Q11: 0.5553 | R11: TinyTS | S11: 0.1972
B12: PatchTS | C12: ='reduction_dist.'!I26 -> 46.12524 | D12: ='reduction_dist.'!J26 -> 1.32 | E12: ='reduction_dist.'!K26 -> 76.47 | G12: ='reduction_dist.'!I27 -> 6.5489866 | H12: ='reduction_dist.'!J27 -> 0 | I12: ='reduction_dist.'!K27 -> 65.71 | K12: ='reduction_dist.'!I28 -> 11.181435 | L12: ='reduction_dist.'!J28 -> 0 | M12: ='reduction_dist.'!K28 -> 76.47 | R12: PatchTS | S12: 0.065
C13: Reduction: needTS&Valid | G13: Reduction: needTS&Invalid | K13: Reduction: needTS&all
A14: shuffle | C14: avg | D14: min | E14: max | G14: avg | H14: min | I14: max | K14: avg | L14: min | M14: max
A15: vm96 | B15: DupNAS | C15: ='reduction_dist.'!I29 -> 40.29802 | D15: ='reduction_dist.'!J29 -> 25 | E15: ='reduction_dist.'!K29 -> 54.17 | G15: ='reduction_dist.'!I30 -> 16.326836 | H15: ='reduction_dist.'!J30 -> 0 | I15: ='reduction_dist.'!K30 -> 33.33 | K15: ='reduction_dist.'!I31 -> 27.232895 | L15: ='reduction_dist.'!J31 -> 0 | M15: ='reduction_dist.'!K31 -> 54.17 | O15: vm96 | P15: before TS valids | Q15: 0.4588 | R15: DupNAS | S15: 0.2462
B16: TinyTS | C16: ='reduction_dist.'!I32 -> 33.024792 | D16: ='reduction_dist.'!J32 -> 32.46 | E16: ='reduction_dist.'!K32 -> 33.22 | G16: ='reduction_dist.'!I33 -> 20.954115 | H16: ='reduction_dist.'!J33 -> 0 | I16: ='reduction_dist.'!K33 -> 33.25 | K16: ='reduction_dist.'!I34 -> 23.630293 | L16: ='reduction_dist.'!J34 -> 0 | M16: ='reduction_dist.'!K34 -> 33.25 | P16: before TS invalids | Q16: 0.5412 | R16: TinyTS | S16: 0.12
B17: PatchTS | C17: ='reduction_dist.'!I35 -> 24.718333 | D17: ='reduction_dist.'!J35 -> 23.44 | E17: ='reduction_dist.'!K35 -> 25 | G17: ='reduction_dist.'!I36 -> 7.8697784 | H17: ='reduction_dist.'!J36 -> 0 | I17: ='reduction_dist.'!K36 -> 39.06 | K17: ='reduction_dist.'!I37 -> 10.671386 | L17: ='reduction_dist.'!J37 -> 0 | M17: ='reduction_dist.'!K37 -> 39.06 | R17: PatchTS | S17: 0.09
A18: vm128 | B18: DupNAS | C18: ='reduction_dist.'!I38 -> 32.532727 | D18: ='reduction_dist.'!J38 -> 15.79 | E18: ='reduction_dist.'!K38 -> 33.33 | G18: ='reduction_dist.'!I39 -> 16.707516 | H18: ='reduction_dist.'!J39 -> 0 | I18: ='reduction_dist.'!K39 -> 33.33 | K18: ='reduction_dist.'!I40 -> 22.113644 | L18: ='reduction_dist.'!J40 -> 0 | M18: ='reduction_dist.'!K40 -> 33.33 | O18: vm128 | P18: before TS valids | Q18: 0.5975 | R18: DupNAS | S18: 0.1375
B19: TinyTS | C19: ='reduction_dist.'!I41 -> 32.904771 | D19: ='reduction_dist.'!J41 -> 32.63 | E19: ='reduction_dist.'!K41 -> 33 | G19: ='reduction_dist.'!I42 -> 22.068191 | H19: ='reduction_dist.'!J42 -> 0 | I19: ='reduction_dist.'!K42 -> 33.25 | K19: ='reduction_dist.'!I43 -> 23.290952 | L19: ='reduction_dist.'!J43 -> 0 | M19: ='reduction_dist.'!K43 -> 33.25 | P19: before TS invalids | Q19: 0.4025 | R19: TinyTS | S19: 0.0454
B20: PatchTS | C20: ='reduction_dist.'!I44 -> 37.96 | D20: ='reduction_dist.'!J44 -> 37.96 | E20: ='reduction_dist.'!K44 -> 37.96 | G20: ='reduction_dist.'!I45 -> 1.0911425 | H20: ='reduction_dist.'!J45 -> 0 | I20: ='reduction_dist.'!K45 -> 25 | K20: ='reduction_dist.'!I46 -> 8.2282816 | L20: ='reduction_dist.'!J46 -> 0 | M20: ='reduction_dist.'!K46 -> 37.96 | R20: PatchTS | S20: 0.0779
A21: vm256 | B21: DupNAS | C21: ='reduction_dist.'!I47 -> 33.138864 | D21: ='reduction_dist.'!J47 -> 32.46 | E21: ='reduction_dist.'!K47 -> 33.33 | G21: ='reduction_dist.'!I48 -> 13.02278 | H21: ='reduction_dist.'!J48 -> 0 | I21: ='reduction_dist.'!K48 -> 33.33 | K21: ='reduction_dist.'!I49 -> 18.989798 | L21: ='reduction_dist.'!J49 -> 0 | M21: ='reduction_dist.'!K49 -> 33.33 | O21: vm256 | P21: before TS valids | Q21: 0.8146 | R21: DupNAS | S21: 0.055
B22: TinyTS | C22: ='reduction_dist.'!I50 -> 32.899621 | D22: ='reduction_dist.'!J50 -> 32.46 | E22: ='reduction_dist.'!K50 -> 33.07 | G22: ='reduction_dist.'!I51 -> 13.572939 | H22: ='reduction_dist.'!J51 -> 0 | I22: ='reduction_dist.'!K51 -> 33.07 | K22: ='reduction_dist.'!I52 -> 19.305798 | L22: ='reduction_dist.'!J52 -> 0 | M22: ='reduction_dist.'!K52 -> 33.07 | P22: before TS invalids | Q22: 0.1854 | R22: TinyTS | S22: 0.055
B23: PatchTS | C23: ='reduction_dist.'!I53 -> 0 | D23: ='reduction_dist.'!J53 -> 0 | E23: ='reduction_dist.'!K53 -> 0 | G23: ='reduction_dist.'!I54 -> 0 | H23: ='reduction_dist.'!J54 -> 0 | I23: ='reduction_dist.'!K54 -> 0 | K23: ='reduction_dist.'!I55 -> 0 | L23: ='reduction_dist.'!J55 -> 0 | M23: ='reduction_dist.'!K55 -> 0 | R23: PatchTS | S23: 0
C24: Reduction: needTS&Valid | G24: Reduction: needTS&Invalid | K24: Reduction: needTS&all
A25: incept | C25: avg | D25: min | E25: max | G25: avg | H25: min | I25: max | K25: avg | L25: min | M25: max
A26: vm96 | B26: DupNAS | C26: ='reduction_dist.'!I56 -> 45.853029 | D26: ='reduction_dist.'!J56 -> 13.64 | E26: ='reduction_dist.'!K56 -> 57.58 | G26: ='reduction_dist.'!I57 -> 6.1360229 | H26: ='reduction_dist.'!J57 -> 0 | I26: ='reduction_dist.'!K57 -> 40.35 | K26: ='reduction_dist.'!I58 -> 12.898057 | L26: ='reduction_dist.'!J58 -> 0 | M26: ='reduction_dist.'!K58 -> 57.58 | O26: vm96 | P26: before TS valids | Q26: 0.3759 | R26: DupNAS | S26: 0.1062
B27: TinyTS | C27: ='reduction_dist.'!I59 -> 26.932353 | D27: ='reduction_dist.'!J59 -> 15.79 | E27: ='reduction_dist.'!K59 -> 27.27 | G27: ='reduction_dist.'!I60 -> 15.006158 | H27: ='reduction_dist.'!J60 -> 0 | I27: ='reduction_dist.'!K60 -> 27.27 | K27: ='reduction_dist.'!I61 -> 15.615308 | L27: ='reduction_dist.'!J61 -> 0 | M27: ='reduction_dist.'!K61 -> 27.27 | P27: before TS invalids | Q27: 0.6241 | R27: TinyTS | S27: 0.0319
B28: PatchTS | C28: ='reduction_dist.'!I62 -> 22.934062 | D28: ='reduction_dist.'!J62 -> 14.58 | E28: ='reduction_dist.'!K62 -> 28.65 | G28: ='reduction_dist.'!I63 -> 4.4212916 | H28: ='reduction_dist.'!J63 -> 0 | I28: ='reduction_dist.'!K63 -> 44.01 | K28: ='reduction_dist.'!I64 -> 6.4978368 | L28: ='reduction_dist.'!J64 -> 0 | M28: ='reduction_dist.'!K64 -> 44.01 | R28: PatchTS | S28: 0.07
A29: vm128 | B29: DupNAS | C29: ='reduction_dist.'!I65 -> 33.594444 | D29: ='reduction_dist.'!J65 -> 12.28 | E29: ='reduction_dist.'!K65 -> 57.58 | G29: ='reduction_dist.'!I66 -> 8.4104217 | H29: ='reduction_dist.'!J66 -> 0 | I29: ='reduction_dist.'!K66 -> 40.35 | K29: ='reduction_dist.'!I67 -> 16.216871 | L29: ='reduction_dist.'!J67 -> 0 | M29: ='reduction_dist.'!K67 -> 57.58 | O29: vm128 | P29: before TS valids | Q29: 0.4738 | R29: DupNAS | S29: 0.1631
B30: TinyTS | C30: ='reduction_dist.'!I68 -> 26.642941 | D30: ='reduction_dist.'!J68 -> 15.79 | E30: ='reduction_dist.'!K68 -> 27.27 | G30: ='reduction_dist.'!I69 -> 16.80601 | H30: ='reduction_dist.'!J69 -> 0 | I30: ='reduction_dist.'!K69 -> 27.27 | K30: ='reduction_dist.'!I70 -> 18.196265 | L30: ='reduction_dist.'!J70 -> 0 | M30: ='reduction_dist.'!K70 -> 27.27 | P30: before TS invalids | Q30: 0.5262 | R30: TinyTS | S30: 0.0744
B31: PatchTS | C31: ='reduction_dist.'!I71 -> 36.679 | D31: ='reduction_dist.'!J71 -> 33.85 | E31: ='reduction_dist.'!K71 -> 37.76 | G31: ='reduction_dist.'!I72 -> 1.810243 | H31: ='reduction_dist.'!J72 -> 0 | I31: ='reduction_dist.'!K72 -> 32.29 | K31: ='reduction_dist.'!I73 -> 4.2949525 | L31: ='reduction_dist.'!J73 -> 0 | M31: ='reduction_dist.'!K73 -> 37.76 | R31: PatchTS | S31: 0.0375
A32: vm256 | B32: DupNAS | C32: ='reduction_dist.'!I74 -> 29.172516 | D32: ='reduction_dist.'!J74 -> 13.64 | E32: ='reduction_dist.'!K74 -> 54.55 | G32: ='reduction_dist.'!I75 -> 8.1769115 | H32: ='reduction_dist.'!J75 -> 0 | I32: ='reduction_dist.'!K75 -> 27.27 | K32: ='reduction_dist.'!I76 -> 14.897217 | L32: ='reduction_dist.'!J76 -> 0 | M32: ='reduction_dist.'!K76 -> 54.55 | O32: vm256 | P32: before TS valids | Q32: 0.6934 | R32: DupNAS | S32: 0.0981
B33: TinyTS | C33: ='reduction_dist.'!I77 -> 26.885911 | D33: ='reduction_dist.'!J77 -> 15.79 | E33: ='reduction_dist.'!K77 -> 27.27 | G33: ='reduction_dist.'!I78 -> 20.248947 | H33: ='reduction_dist.'!J78 -> 0 | I33: ='reduction_dist.'!K78 -> 27.27 | K33: ='reduction_dist.'!I79 -> 22.068869 | L33: ='reduction_dist.'!J79 -> 0 | M33: ='reduction_dist.'!K79 -> 27.27 | P33: before TS invalids | Q33: 0.3066 | R33: TinyTS | S33: 0.0841
B34: PatchTS | C34: ='reduction_dist.'!I80 -> 0 | D34: ='reduction_dist.'!J80 -> 0 | E34: ='reduction_dist.'!K80 -> 0 | G34: ='reduction_dist.'!I81 -> 0 | H34: ='reduction_dist.'!J81 -> 0 | I34: ='reduction_dist.'!K81 -> 0 | K34: ='reduction_dist.'!I82 -> 0 | L34: ='reduction_dist.'!J82 -> 0 | M34: ='reduction_dist.'!K82 -> 0 | R34: PatchTS | S34: 0
C38: overall mem reduction | K38: overall mem reduction | P38: Overall feasible expansion
A39: only MB nets | Q39: min | R39: max
B40: DupNAS | D40: =MIN(D15,D18,D21,D26,D29,D32) -> 12.28 | E40: =MAX(E15,E18,E21,E26,E29,E32) -> 57.58 | K40: DupNAS | L40: =MIN(L15,L18,L21,L26,L29,L32) -> 0 | M40: =MAX(M15,M18,M21,M26,M29,M32) -> 57.58 | P40: DupNAS | Q40: =MIN(S4,S7,S10,S15,S18,S21,S26,S29,S32) -> 0.055 | R40: =MAX(S4,S7,S10,S15,S18,S21,S26,S29,S32) -> 0.5847
B41: TinyTS | D41: =MIN(D16,D19,D22,D27,D30,D33) -> 15.79 | E41: =MAX(E16,E19,E22,E27,E30,E33) -> 33.22 | K41: TinyTS | L41: =MIN(L16,L19,L22,L27,L30,L33) -> 0 | M41: =MAX(M16,M19,M22,M27,M30,M33) -> 33.25 | P41: TinyTS | Q41: =MIN(S5,S8,S11,S16,S19,S22,S27,S30,S33) -> 0.0319 | R41: =MAX(S5,S8,S11,S16,S19,S22,S27,S30,S33) -> 0.1972
B42: PatchTS | D42: =MIN(D17,D20,D23,D28,D31,D34) -> 0 | E42: =MAX(E17,E20,E23,E28,E31,E34) -> 37.96 | K42: PatchTS | L42: =MIN(L17,L20,L23,L28,L31,L34) -> 0 | M42: =MAX(M17,M20,M23,M28,M31,M34) -> 44.01 | P42: PatchTS | Q42: =MIN(S6,S9,S12,S17,S20,S23,S28,S31,S34) -> 0 | R42: =MAX(S6,S9,S12,S17,S20,S23,S28,S31,S34) -> 0.09
A46: all networks
...

Sheet Accuracy
A2: mbv2 | C2: vm96 | D2: vm128 | E2: vm256 | H2: vm96 | I2: vm128 | J2: vm256
B3: DupNAS | C3: 58.4 | D3: 62.08 | E3: 62.64 | G3: vs TinyTS | H3: =C3-C4 -> 5.52 | I3: =D3-D4 -> 5.2 | J3: =E3-E4 -> 0.88
B4: TinyTS | C4: 52.88 | D4: 56.88 | E4: 61.76 | G4: vs PatchTS | H4: =C3-C5 -> 7.04 | I4: =D3-D5 -> 5.6 | J4: =E3-E5 -> 0
B5: PatchTS | C5: 51.36 | D5: 56.48 | E5: 62.64 | G5: vs NoTS | H5: =C3-C6 -> 18.72 | I5: =D3-D6 -> 21.44 | J5: =E3-E6 -> 9.28
B6: NoTS | C6: 39.68 | D6: 40.64 | E6: 53.36
A8: shuffle | C8: vm96 | D8: vm128 | E8: vm256 | H8: vm96 | I8: vm128 | J8: vm256
B9: DupNAS | C9: 61.36 | D9: 62.96 | E9: 65.76 | G9: vs TinyTS | H9: =C9-C10 -> 4.56 | I9: =D9-D10 -> 3.2 | J9: =E9-E10 -> 0.8
B10: TinyTS | C10: 56.8 | D10: 59.76 | E10: 64.96 | G10: vs PatchTS | H10: =C9-C11 -> 7.12 | I10: =D9-D11 -> 4.24 | J10: =E9-E11 -> 5.28
B11: PatchTS | C11: 54.24 | D11: 58.72 | E11: 60.48 | G11: vs NoTS | H11: =C9-C12 -> 13.28 | I11: =D9-D12 -> 6.24 | J11: =E9-E12 -> 5.36
B12: NoTS | C12: 48.08 | D12: 56.72 | E12: 60.4
A14: incept | C14: vm96 | D14: vm128 | E14: vm256 | H14: vm96 | I14: vm128 | J14: vm256
B15: DupNAS | C15: 61.84 | D15: 64.16 | E15: 68.24 | G15: vs TinyTS | H15: =C15-C16 -> 16.16 | I15: =D15-D16 -> 6.32 | J15: =E15-E16 -> 3.36
B16: TinyTS | C16: 45.68 | D16: 57.84 | E16: 64.88 | G16: vs PatchTS | H16: =C15-C17 -> 7.84 | I16: =D15-D17 -> 5.52 | J16: =E15-E17 -> 0.88
B17: PatchTS | C17: 54 | D17: 58.64 | E17: 67.36 | G17: vs NoTS | H17: =C15-C18 -> 17.04 | I17: =D15-D18 -> 15.2 | J17: =E15-E18 -> 8.96
B18: NoTS | C18: 44.8 | D18: 48.96 | E18: 59.28
H19: min | I19: avg | J19: max
G20: vs TinyTS | H20: =MIN(H3:J3,H9:J9,H15:J15) -> 0.8 | I20: =AVERAGE(H3:J3,H9:J9,H15:J15) -> 5.1111111 | J20: =MAX(H3:J3,H9:J9,H15:J15) -> 16.16
G21: vs PatchTS | H21: =MIN(H4:J4,H10:J10,H16:J16) -> 0 | I21: =AVERAGE(H4:J4,H10:J10,H16:J16) -> 4.8355556 | J21: =MAX(H4:J4,H10:J10,H16:J16) -> 7.84
G22: vs NoTS | H22: =MIN(H5:J5,H11:J11,H17:J17) -> 5.36 | I22: =AVERAGE(H5:J5,H11:J11,H17:J17) -> 12.835556 | J22: =MAX(H5:J5,H11:J11,H17:J17) -> 21.44
G24: overall avg | I24: =AVERAGE(H3:J4,H9:J10,H15:J16) -> 4.9733333

Sheet Inference lat.
G1: vm128 | N1: vm96
C2: vm96 | D2: vm128 | E2: vm256 | G2: TS | H2: Accu. | I2: Inf. Lat.(s) | K2: vs TinyTS | L2: <-- strongest | N2: TS | O2: Accu. | P2: Inf. Lat.(s) | R2: vs TinyTS
A3: mbv2 | C3: lat. (ms) | D3: lat. (ms) | E3: lat. (ms) | G3: DupNAS* | H3: 62.08 | I3: 3.575 | K3: Accu. | L3: Inf. Lat.(s) | N3: DupNAS* | O3: 58.4 | P3: =C4/1000 -> 1.711 | R3: Accu. | S3: Inf. Lat.(s)
B4: DupNAS | C4: 1711 | D4: 3575 | E4: 2976 | G4: TinyTS* | H4: 56.88 | I4: 2.153 | K4: =H6-H4 -> 2.72 | L4: =(I6-I4)/I4 -> -0.073385973 | N4: TinyTS* | O4: 52.88 | P4: =C5/1000 -> 1.25 | R4: =O6-O4 -> 4.8 | S4: =(P6-P4)/P4 -> -0.0208
B5: TinyTS | C5: 1250 | D5: 2153 | G5: PatchTS* | H5: 56.48 | I5: 1.188 | N5: PatchTS* | O5: 51.36 | P5: =C6/1000 -> 1.205
B6: PatchTS | C6: 1205 | D6: 1188 | E6: 3573 | G6: DupNAS | H6: 59.6 | I6: 1.995 | N6: DupNAS | O6: 57.68 | P6: 1.224
B7: NoTS | C7: 291 | D7: 248 | E7: 798 | G7: DupNAS | H7: 60.32 | I7: 2.232 | N7: DupNAS | O7: 58 | P7: 1.403
G8: DupNAS | H8: 60.56 | I8: 2.396
G9: DupNAS | H9: 60.72 | I9: 2.494
G10: DupNAS | H10: 61.28 | I10: 2.519
G11: DupNAS | H11: 61.68 | I11: 2.531
C13: vm96 | D13: vm128 | E13: vm256 | G13: TS | H13: Accu. | I13: Inf. Lat.(s) | K13: vs TinyTS | N13: TS | O13: Accu. | P13: Inf. Lat.(s) | R13: vs TinyTS
A14: shuffle | C14: lat. (ms) | D14: lat. (ms) | E14: lat. (ms) | G14: DupNAS* | H14: 62.96 | I14: 2.558 | K14: Accu. | L14: Inf. Lat.(ms) | N14: DupNAS* | O14: 61.36 | P14: =C15/1000 -> 2.443 | R14: Accu. | S14: Inf. Lat.(s)
B15: DupNAS | C15: 2443 | D15: 2558 | E15: 6703 | G15: TinyTS* | H15: 59.76 | I15: 3.021 | K15: =H14-H15 -> 3.2 | L15: =(I14-I15)/I15 -> -0.15326051 | N15: TinyTS* | O15: 56.8 | P15: =C16/1000 -> 1.411 | R15: =O18-O15 -> 2.16 | S15: =(P18-P15)/P15 -> -0.1318214
B16: TinyTS | C16: 1411 | D16: 3021 | G16: PatchTS* | H16: 58.72 | I16: 1.554 | N16: PatchTS* | O16: 54.24 | P16: =C17/1000 -> 1.122
B17: PatchTS | C17: 1122 | D17: 1554 | E17: 3376 | G17: DupNAS | H17: 59.12 | I17: 1.785 | N17: DupNAS | O17: 55.6 | P17: 1.124
B18: NoTS | C18: 599 | D18: 1346 | E18: 3802 | G18: DupNAS | H18: 60.4 | I18: 1.936 | N18: DupNAS | O18: 58.96 | P18: 1.225
G19: DupNAS | H19: 60.72 | I19: 1.982 | N19: DupNAS | O19: 59.28 | P19: 1.529
G20: DupNAS | H20: 61.6 | I20: 2.317 | N20: DupNAS | O20: 61.2 | P20: 1.589
C23: vm96 | D23: vm128 | E23: vm256 | G23: TS | H23: Accu. | I23: Inf. Lat.(s) | K23: vs PatchTS | N23: TS | O23: Accu. | P23: Inf. Lat.(s) | R23: vs PatchTS
A24: incept | C24: lat. (ms) | D24: lat. (ms) | E24: lat. (ms) | G24: DupNAS* | H24: 64.16 | I24: 4.623 | K24: Accu. | L24: Inf. Lat.(ms) | N24: DupNAS* | O24: 61.84 | P24: =C25/1000 -> 3.545 | R24: Accu. | S24: Inf. Lat.(s)
B25: DupNAS | C25: 3545 | D25: 4623 | E25: 4950 | G25: TinyTS* | H25: 57.84 | I25: 0.808 | K25: =H27-H26 -> -0.4 | L25: =(I27-I26)/I26 -> -0.28100325 | N25: TinyTS* | O25: 45.68 | P25: =C26/1000 -> 0.614 | R25: =O27-O26 -> 1.44 | S25: =(P27-P26)/P26 -> 0.080760095
B26: TinyTS | C26: 614 | D26: 808 | G26: PatchTS* | H26: 58.64 | I26: 2.153 | N26: PatchTS* | O26: 54 | P26: =C27/1000 -> 1.263
B27: PatchTS | C27: 1263 | D27: 2153 | E27: 5140 | G27: DupNAS | H27: 58.24 | I27: 1.548 | N27: DupNAS | O27: 55.44 | P27: 1.365
B28: NoTS | C28: 491 | D28: 1020 | E28: 2564 | G28: DupNAS | H28: 58.88 | I28: 2.314 | N28: DupNAS | O28: 59.84 | P28: 1.829
G29: DupNAS | H29: 59.36 | I29: 2.725
G30: DupNAS | H30: 61.04 | I30: 3.622
G31: DupNAS | H31: 61.2 | I31: 3.752
I35: Averages | K35: =AVERAGE(K4,K15,K25) -> 1.84 | L35: =AVERAGE(L4,L15,L25,S4,S15,S25) -> -0.096585174

Sheet Search time
C1: NAS time(s) | F1: total NAS time(hrs) | K1: TS time per network (s)
A2: mbv2 | C2: for TS | D2: not for TS | E2: total | F2: for TS | G2: not for TS | H2: total | J2: mbv2 | L2: max | M2: avg | N2: min | Q2: min | R2: avg | S2: max
B3: DupNAS | C3: 22382 | D3: 20225 | E3: =C3+D3 -> 42607 | F3: =C3/3600 -> 6.2172222 | G3: =D3/3600 -> 5.6180556 | H3: =E3/3600 -> 11.835278 | K3: DupNAS | L3: 6.975875 | M3: 5.0815125 | N3: 3.2858875 | P3: vs TinyTS | Q3: =MIN(O21:O23) -> 0.00050888605 | R3: =AVERAGE(O21:O23) -> 0.16351326 | S3: =MAX(O21:O23) -> 0.30384923
B4: TinyTS | C4: 21368 | D4: 18859 | E4: =C4+D4 -> 40227 | F4: =C4/3600 -> 5.9355556 | G4: =D4/3600 -> 5.2386111 | H4: =E4/3600 -> 11.174167 | K4: TinyTS | L4: 5.88095 | M4: 4.4604448 | N4: 2.5201437 | P4: vs PatchTS | Q4: =MIN(P21:P23) -> -0.0086736483 | R4: =AVERAGE(P21:P23) -> 0.055431815 | S4: =MAX(P21:P23) -> 0.17065261
B5: PatchTS | C5: 21604 | D5: 18676 | E5: =C5+D5 -> 40280 | F5: =C5/3600 -> 6.0011111 | G5: =D5/3600 -> 5.1877778 | H5: =E5/3600 -> 11.188889 | K5: PatchTS | L5: 5.9589625 | M5: 4.7449865 | N5: 3.3146375
B6: NoTS | D6: 16355 | E6: =C6+D6 -> 16355 | F6: =C6/3600 -> 0 | G6: =D6/3600 -> 4.5430556 | H6: =E6/3600 -> 4.5430556
A8: shuffle | J8: shuffle | L8: max | M8: avg | N8: min | Q8: min | R8: avg | S8: max
B9: DupNAS | C9: 8746 | D9: 18850 | E9: =C9+D9 -> 27596 | F9: =C9/3600 -> 2.4294444 | G9: =D9/3600 -> 5.2361111 | H9: =E9/3600 -> 7.6655556 | K9: DupNAS | L9: 2.9472083 | M9: 2.5454792 | N9: 2.3347458 | P9: vs TinyTS | Q9: =MIN(O28:O30) -> 0.020242436 | R9: =AVERAGE(O28:O30) -> 0.03325408 | S9: =MAX(O28:O30) -> 0.05025622
B10: TinyTS | C10: 8461 | D10: 18596 | E10: =C10+D10 -> 27057 | F10: =C10/3600 -> 2.3502778 | G10: =D10/3600 -> 5.1655556 | H10: =E10/3600 -> 7.5158333 | K10: TinyTS | L10: 2.8887333 | M10: 2.4664333 | N10: 2.223025 | P10: vs PatchTS | Q10: =MIN(P28:P30) -> 0.023106421 | R10: =AVERAGE(P28:P30) -> 0.03505705 | S10: =MAX(P28:P30) -> 0.048883989
B11: PatchTS | C11: 8401 | D11: 19805 | E11: =C11+D11 -> 28206 | F11: =C11/3600 -> 2.3336111 | G11: =D11/3600 -> 5.5013889 | H11: =E11/3600 -> 7.835 | K11: PatchTS | L11: 2.8525583 | M11: 2.4599333 | N11: 2.2259333
B12: NoTS | D12: 18054 | E12: =C12+D12 -> 18054 | F12: =C12/3600 -> 0 | G12: =D12/3600 -> 5.015 | H12: =E12/3600 -> 5.015
A14: incept | J14: incept | L14: max | M14: avg | N14: min | Q14: min | R14: avg | S14: max
B15: DupNAS | C15: 16734 | D15: 21050 | E15: =C15+D15 -> 37784 | F15: =C15/3600 -> 4.6483333 | G15: =D15/3600 -> 5.8472222 | H15: =E15/3600 -> 10.495556 | K15: DupNAS | L15: 4.42835 | M15: 3.80635 | N15: 3.4325437 | P15: vs TinyTS | Q15: =MIN(O35:O37) -> -0.18268361 | R15: =AVERAGE(O35:O37) -> -0.044908952 | S15: =MAX(O35:O37) -> 0.043332314
B16: TinyTS | C16: 16918 | D16: 19734 | E16: =C16+D16 -> 36652 | F16: =C16/3600 -> 4.6994444 | G16: =D16/3600 -> 5.4816667 | H16: =E16/3600 -> 10.181111 | K16: TinyTS | L16: 4.4079656 | M16: 4.0171365 | N16: 3.2899813 | P16: vs PatchTS | Q16: =MIN(P35:P37) -> -0.027067102 | R16: =AVERAGE(P35:P37) -> -0.0088084352 | S16: =MAX(P35:P37) -> 0.0063181068
B17: PatchTS | C17: 16696 | D17: 20699 | E17: =C17+D17 -> 37395 | F17: =C17/3600 -> 4.6377778 | G17: =D17/3600 -> 5.7497222 | H17: =E17/3600 -> 10.3875 | K17: PatchTS | L17: 4.4005469 | M17: 3.8356844 | N17: 3.5280375
B18: NoTS | D18: 18305 | E18: =C18+D18 -> 18305 | F18: =C18/3600 -> 0 | G18: =D18/3600 -> 5.0847222 | H18: =E18/3600 -> 5.0847222
J20: mbv2 | K20: DupNAS | L20: TinyTS | M20: PatchTS | O20: vs TinyTS | P20: vs PatchTS | S20: overall min/max
J21: vm256 | K21: 3.2858875 | L21: 2.5201437 | M21: 3.3146375 | O21: =(K21-L21)/L21 -> 0.30384923 | P21: =(K21-M21)/M21 -> -0.0086736483 | T21: min | U21: max
J22: vm128 | K22: 4.982775 | L22: 4.9802406 | M22: 4.9613594 | O22: =(K22-L22)/L22 -> 0.00050888605 | P22: =(K22-M22)/M22 -> 0.0043164833 | S22: vs TinyTS | T22: =MIN(O21:O37) -> -0.18268361 | U22: =MAX(O21:O37) -> 0.30384923
J23: vm96 | K23: 6.975875 | L23: 5.88095 | M23: 5.9589625 | O23: =(K23-L23)/L23 -> 0.18618165 | P23: =(K23-M23)/M23 -> 0.17065261 | S23: vs PatchTS | T23: =MIN(P21:P37) -> -0.027067102 | U23: =MAX(P21:P37) -> 0.17065261
J24: max | K24: 6.975875 | L24: 5.88095 | M24: 5.9589625
J25: avg | K25: 5.0815125 | L25: 4.4604448 | M25: 4.7449865
J26: min | K26: 3.2858875 | L26: 2.5201437 | M26: 3.3146375
J27: shuffle | K27: DupNAS | L27: TinyTS | M27: PatchTS
J28: vm256 | K28: 2.9472083 | L28: 2.8887333 | M28: 2.8525583 | O28: =(K28-L28)/L28 -> 0.020242436 | P28: =(K28-M28)/M28 -> 0.033180741
J29: vm128 | K29: 2.3347458 | L29: 2.223025 | M29: 2.2259333 | O29: =(K29-L29)/L29 -> 0.05025622 | P29: =(K29-M29)/M29 -> 0.048883989
J30: vm96 | K30: 2.3544833 | L30: 2.2875417 | M30: 2.3013083 | O30: =(K30-L30)/L30 -> 0.029263584 | P30: =(K30-M30)/M30 -> 0.023106421
J31: max | K31: 2.9472083 | L31: 2.8887333 | M31: 2.8525583
J32: avg | K32: 2.5454792 | L32: 2.4664333 | M32: 2.4599333
J33: min | K33: 2.3347458 | L33: 2.223025 | M33: 2.2259333
J34: incept | K34: DupNAS | L34: TinyTS | M34: PatchTS
J35: vm256 | K35: 3.5581563 | L35: 4.3534625 | M35: 3.5784688 | O35: =(K35-L35)/L35 -> -0.18268361 | P35: =(K35-M35)/M35 -> -0.0056763106
J36: vm128 | K36: 4.42835 | L36: 4.4079656 | M36: 4.4005469 | O36: =(K36-L36)/L36 -> 0.0046244406 | P36: =(K36-M36)/M36 -> 0.0063181068
J37: vm96 | K37: 3.4325437 | L37: 3.2899813 | M37: 3.5280375 | O37: =(K37-L37)/L37 -> 0.043332314 | P37: =(K37-M37)/M37 -> -0.027067102
J38: max | K38: 4.42835 | L38: 4.4079656 | M38: 4.4005469
J39: avg | K39: 3.80635 | L39: 4.0171365 | M39: 3.8356844
J40: min | K40: 3.4325437 | L40: 3.2899813 | M40: 3.5280375

Sheet reduction_dist.
A1: model | B1: model_title | C1: vm | D1: vm_kb | E1: method | F1: method_label | G1: subset | H1: sample_count | I1: avg_reduction | J1: min_reduction | K1: max_reduction | L1: count_red_0 | M1: count_red_1 | N1: count_red_2 | O1: count_red_3 | P1: count_red_4 | Q1: count_red_5 | R1: count_red_6 | S1: count_red_7 | T1: count_red_8 | U1: count_red_9 | V1: count_red_10 | W1: count_red_11 | X1: count_red_12 | Y1: count_red_13 | Z1: count_red_14 | AA1: count_red_15 | AB1: count_red_16 | AC1: count_red_17 | AD1: count_red_18 | AE1: count_red_19 | AF1: count_red_20 | AG1: count_red_21 | AH1: count_red_22 | AI1: count_red_23 | AJ1: count_red_24 | AK1: count_red_25 | AL1: count_red_26 | AM1: count_red_27 | AN1: count_red_28 | AO1: count_red_29 | AP1: count_red_30 | AQ1: count_red_31 | AR1: count_red_32 | AS1: count_red_33 | AT1: count_red_34 | AU1: count_red_35 | AV1: count_red_36 | AW1: count_red_37 | AX1: count_red_38 | AY1: count_red_39 | AZ1: count_red_40 | BA1: count_red_41 | BB1: count_red_42 | BC1: count_red_43 | BD1: count_red_44 | BE1: count_red_45 | BF1: count_red_46 | BG1: count_red_47 | BH1: count_red_48 | BI1: count_red_49 | BJ1: count_red_50 | BK1: count_red_51 | BL1: count_red_52 | BM1: count_red_53 | BN1: count_red_54 | BO1: count_red_55 | BP1: count_red_56 | BQ1: count_red_57 | BR1: count_red_58 | BS1: count_red_59 | BT1: count_red_60 | BU1: count_red_61 | BV1: count_red_62 | BW1: count_red_63 | BX1: count_red_64 | BY1: count_red_65 | BZ1: count_red_66 | CA1: count_red_67 | CB1: count_red_68 | CC1: count_red_69 | CD1: count_red_70 | CE1: count_red_71 | CF1: count_red_72 | CG1: count_red_73 | CH1: count_red_74 | CI1: count_red_75 | CJ1: count_red_76 | CK1: count_red_77 | CL1: count_red_78 | CM1: count_red_79 | CN1: count_red_80 | CO1: count_red_81 | CP1: count_red_82 | CQ1: count_red_83 | CR1: count_red_84 | CS1: count_red_85 | CT1: count_red_86 | CU1: count_red_87 | CV1: count_red_88 | CW1: count_red_89 | CX1: count_red_90 | CY1: count_red_91 | CZ1: count_red_92 | DA1: count_red_93 | DB1: count_red_94 | DC1: count_red_95 | DD1: count_red_96 | DE1: count_red_97 | DF1: count_red_98 | DG1: count_red_99 | DH1: count_red_100
A2: mbv2 | B2: MobileNet | C2: vm96 | D2: 96 | E2: ourTS | F2: DupNAS | G2: needTS_valid | H2: 1810 | I2: 64.456017 | J2: 20 | K2: 88.84 | L2: 0 | M2: 0 | N2: 0 | O2: 0 | P2: 0 | Q2: 0 | R2: 0 | S2: 0 | T2: 0 | U2: 0 | V2: 0 | W2: 0 | X2: 0 | Y2: 0 | Z2: 0 | AA2: 0 | AB2: 0 | AC2: 0 | AD2: 0 | AE2: 0 | AF2: 3 | AG2: 0 | AH2: 80 | AI2: 0 | AJ2: 0 | AK2: 0 | AL2: 27 | AM2: 0 | AN2: 41 | AO2: 40 | AP2: 2 | AQ2: 12 | AR2: 0 | AS2: 0 | AT2: 0 | AU2: 0 | AV2: 1 | AW2: 4 | AX2: 18 | AY2: 0 | AZ2: 126 | BA2: 9 | BB2: 48 | BC2: 16 | BD2: 0 | BE2: 17 | BF2: 0 | BG2: 0 | BH2: 0 | BI2: 0 | BJ2: 0 | BK2: 0 | BL2: 0 | BM2: 11 | BN2: 0 | BO2: 34 | BP2: 31 | BQ2: 6 | BR2: 0 | BS2: 0 | BT2: 22 | BU2: 70 | BV2: 66 | BW2: 21 | BX2: 29 | BY2: 30 | BZ2: 7 | CA2: 0 | CB2: 13 | CC2: 43 | CD2: 11 | CE2: 66 | CF2: 72 | CG2: 65 | CH2: 47 | CI2: 0 | CJ2: 110 | CK2: 0 | CL2: 24 | CM2: 78 | CN2: 85 | CO2: 60 | CP2: 96 | CQ2: 21 | CR2: 60 | CS2: 12 | CT2: 69 | CU2: 0 | CV2: 89 | CW2: 18 | CX2: 0 | CY2: 0 | CZ2: 0 | DA2: 0 | DB2: 0 | DC2: 0 | DD2: 0 | DE2: 0 | DF2: 0 | DG2: 0 | DH2: 0
A3: mbv2 | B3: MobileNet | C3: vm96 | D3: 96 | E3: ourTS | F3: DupNAS | G3: needTS_invalid | H3: 723 | I3: 41.221812 | J3: 0 | K3: 88 | L3: 338 | M3: 0 | N3: 0 | O3: 7 | P3: 0 | Q3: 0 | R3: 0 | S3: 0 | T3: 0 | U3: 0 | V3: 0 | W3: 0 | X3: 0 | Y3: 0 | Z3: 0 | AA3: 0 | AB3: 0 | AC3: 0 | AD3: 0 | AE3: 0 | AF3: 0 | AG3: 0 | AH3: 0 | AI3: 12 | AJ3: 0 | AK3: 6 | AL3: 0 | AM3: 0 | AN3: 0 | AO3: 0 | AP3: 0 | AQ3: 0 | AR3: 0 | AS3: 0 | AT3: 0 | AU3: 0 | AV3: 0 | AW3: 0 | AX3: 0 | AY3: 0 | AZ3: 0 | BA3: 3 | BB3: 0 | BC3: 0 | BD3: 0 | BE3: 0 | BF3: 0 | BG3: 0 | BH3: 0 | BI3: 0 | BJ3: 0 | BK3: 0 | BL3: 0 | BM3: 0 | BN3: 0 | BO3: 0 | BP3: 0 | BQ3: 0 | BR3: 0 | BS3: 0 | BT3: 0 | BU3: 0 | BV3: 0 | BW3: 0 | BX3: 0 | BY3: 0 | BZ3: 0 | CA3: 0 | CB3: 0 | CC3: 0 | CD3: 0 | CE3: 0 | CF3: 0 | CG3: 0 | CH3: 0 | CI3: 0 | CJ3: 0 | CK3: 130 | CL3: 0 | CM3: 0 | CN3: 0 | CO3: 0 | CP3: 131 | CQ3: 0 | CR3: 0 | CS3: 0 | CT3: 0 | CU3: 4 | CV3: 92 | CW3: 0 | CX3: 0 | CY3: 0 | CZ3: 0 | DA3: 0 | DB3: 0 | DC3: 0 | DD3: 0 | DE3: 0 | DF3: 0 | DG3: 0 | DH3: 0
A4: mbv2 | B4: MobileNet | C4: vm96 | D4: 96 | E4: ourTS | F4: DupNAS | G4: needTS_all | H4: 2533 | I4: 57.824224 | J4: 0 | K4: 88.84 | L4: 338 | M4: 0 | N4: 0 | O4: 7 | P4: 0 | Q4: 0 | R4: 0 | S4: 0 | T4: 0 | U4: 0 | V4: 0 | W4: 0 | X4: 0 | Y4: 0 | Z4: 0 | AA4: 0 | AB4: 0 | AC4: 0 | AD4: 0 | AE4: 0 | AF4: 3 | AG4: 0 | AH4: 80 | AI4: 12 | AJ4: 0 | AK4: 6 | AL4: 27 | AM4: 0 | AN4: 41 | AO4: 40 | AP4: 2 | AQ4: 12 | AR4: 0 | AS4: 0 | AT4: 0 | AU4: 0 | AV4: 1 | AW4: 4 | AX4: 18 | AY4: 0 | AZ4: 126 | BA4: 12 | BB4: 48 | BC4: 16 | BD4: 0 | BE4: 17 | BF4: 0 | BG4: 0 | BH4: 0 | BI4: 0 | BJ4: 0 | BK4: 0 | BL4: 0 | BM4: 11 | BN4: 0 | BO4: 34 | BP4: 31 | BQ4: 6 | BR4: 0 | BS4: 0 | BT4: 22 | BU4: 70 | BV4: 66 | BW4: 21 | BX4: 29 | BY4: 30 | BZ4: 7 | CA4: 0 | CB4: 13 | CC4: 43 | CD4: 11 | CE4: 66 | CF4: 72 | CG4: 65 | CH4: 47 | CI4: 0 | CJ4: 110 | CK4: 130 | CL4: 24 | CM4: 78 | CN4: 85 | CO4: 60 | CP4: 227 | CQ4: 21 | CR4: 60 | CS4: 12 | CT4: 69 | CU4: 4 | CV4: 181 | CW4: 18 | CX4: 0 | CY4: 0 | CZ4: 0 | DA4: 0 | DB4: 0 | DC4: 0 | DD4: 0 | DE4: 0 | DF4: 0 | DG4: 0 | DH4: 0
A5: mbv2 | B5: MobileNet | C5: vm96 | D5: 96 | E5: tinyTS | F5: TinyTS | G5: needTS_valid | H5: 444 | I5: 45.349414 | J5: 29.46 | K5: 47.75 | L5: 0 | M5: 0 | N5: 0 | O5: 0 | P5: 0 | Q5: 0 | R5: 0 | S5: 0 | T5: 0 | U5: 0 | V5: 0 | W5: 0 | X5: 0 | Y5: 0 | Z5: 0 | AA5: 0 | AB5: 0 | AC5: 0 | AD5: 0 | AE5: 0 | AF5: 0 | AG5: 0 | AH5: 0 | AI5: 0 | AJ5: 0 | AK5: 0 | AL5: 0 | AM5: 0 | AN5: 0 | AO5: 19 | AP5: 0 | AQ5: 0 | AR5: 0 | AS5: 6 | AT5: 12 | AU5: 0 | AV5: 3 | AW5: 0 | AX5: 0 | AY5: 0 | AZ5: 0 | BA5: 0 | BB5: 4 | BC5: 29 | BD5: 0 | BE5: 16 | BF5: 61 | BG5: 126 | BH5: 168 | BI5: 0 | BJ5: 0 | BK5: 0 | BL5: 0 | BM5: 0 | BN5: 0 | BO5: 0 | BP5: 0 | BQ5: 0 | BR5: 0 | BS5: 0 | BT5: 0 | BU5: 0 | BV5: 0 | BW5: 0 | BX5: 0 | BY5: 0 | BZ5: 0 | CA5: 0 | CB5: 0 | CC5: 0 | CD5: 0 | CE5: 0 | CF5: 0 | CG5: 0 | CH5: 0 | CI5: 0 | CJ5: 0 | CK5: 0 | CL5: 0 | CM5: 0 | CN5: 0 | CO5: 0 | CP5: 0 | CQ5: 0 | CR5: 0 | CS5: 0 | CT5: 0 | CU5: 0 | CV5: 0 | CW5: 0 | CX5: 0 | CY5: 0 | CZ5: 0 | DA5: 0 | DB5: 0 | DC5: 0 | DD5: 0 | DE5: 0 | DF5: 0 | DG5: 0 | DH5: 0
A6: mbv2 | B6: MobileNet | C6: vm96 | D6: 96 | E6: tinyTS | F6: TinyTS | G6: needTS_invalid | H6: 2089 | I6: 46.396094 | J6: 29.51 | K6: 48.44 | L6: 0 | M6: 0 | N6: 0 | O6: 0 | P6: 0 | Q6: 0 | R6: 0 | S6: 0 | T6: 0 | U6: 0 | V6: 0 | W6: 0 | X6: 0 | Y6: 0 | Z6: 0 | AA6: 0 | AB6: 0 | AC6: 0 | AD6: 0 | AE6: 0 | AF6: 0 | AG6: 0 | AH6: 0 | AI6: 0 | AJ6: 0 | AK6: 0 | AL6: 0 | AM6: 0 | AN6: 0 | AO6: 0 | AP6: 36 | AQ6: 0 | AR6: 0 | AS6: 14 | AT6: 0 | AU6: 17 | AV6: 8 | AW6: 0 | AX6: 0 | AY6: 0 | AZ6: 0 | BA6: 0 | BB6: 12 | BC6: 13 | BD6: 88 | BE6: 17 | BF6: 454 | BG6: 615 | BH6: 815 | BI6: 0 | BJ6: 0 | BK6: 0 | BL6: 0 | BM6: 0 | BN6: 0 | BO6: 0 | BP6: 0 | BQ6: 0 | BR6: 0 | BS6: 0 | BT6: 0 | BU6: 0 | BV6: 0 | BW6: 0 | BX6: 0 | BY6: 0 | BZ6: 0 | CA6: 0 | CB6: 0 | CC6: 0 | CD6: 0 | CE6: 0 | CF6: 0 | CG6: 0 | CH6: 0 | CI6: 0 | CJ6: 0 | CK6: 0 | CL6: 0 | CM6: 0 | CN6: 0 | CO6: 0 | CP6: 0 | CQ6: 0 | CR6: 0 | CS6: 0 | CT6: 0 | CU6: 0 | CV6: 0 | CW6: 0 | CX6: 0 | CY6: 0 | CZ6: 0 | DA6: 0 | DB6: 0 | DC6: 0 | DD6: 0 | DE6: 0 | DF6: 0 | DG6: 0 | DH6: 0
A7: mbv2 | B7: MobileNet | C7: vm96 | D7: 96 | E7: tinyTS | F7: TinyTS | G7: needTS_all | H7: 2533 | I7: 46.212625 | J7: 29.46 | K7: 48.44 | L7: 0 | M7: 0 | N7: 0 | O7: 0 | P7: 0 | Q7: 0 | R7: 0 | S7: 0 | T7: 0 | U7: 0 | V7: 0 | W7: 0 | X7: 0 | Y7: 0 | Z7: 0 | AA7: 0 | AB7: 0 | AC7: 0 | AD7: 0 | AE7: 0 | AF7: 0 | AG7: 0 | AH7: 0 | AI7: 0 | AJ7: 0 | AK7: 0 | AL7: 0 | AM7: 0 | AN7: 0 | AO7: 19 | AP7: 36 | AQ7: 0 | AR7: 0 | AS7: 20 | AT7: 12 | AU7: 17 | AV7: 11 | AW7: 0 | AX7: 0 | AY7: 0 | AZ7: 0 | BA7: 0 | BB7: 16 | BC7: 42 | BD7: 88 | BE7: 33 | BF7: 515 | BG7: 741 | BH7: 983 | BI7: 0 | BJ7: 0 | BK7: 0 | BL7: 0 | BM7: 0 | BN7: 0 | BO7: 0 | BP7: 0 | BQ7: 0 | BR7: 0 | BS7: 0 | BT7: 0 | BU7: 0 | BV7: 0 | BW7: 0 | BX7: 0 | BY7: 0 | BZ7: 0 | CA7: 0 | CB7: 0 | CC7: 0 | CD7: 0 | CE7: 0 | CF7: 0 | CG7: 0 | CH7: 0 | CI7: 0 | CJ7: 0 | CK7: 0 | CL7: 0 | CM7: 0 | CN7: 0 | CO7: 0 | CP7: 0 | CQ7: 0 | CR7: 0 | CS7: 0 | CT7: 0 | CU7: 0 | CV7: 0 | CW7: 0 | CX7: 0 | CY7: 0 | CZ7: 0 | DA7: 0 | DB7: 0 | DC7: 0 | DD7: 0 | DE7: 0 | DF7: 0 | DG7: 0 | DH7: 0
A8: mbv2 | B8: MobileNet | C8: vm96 | D8: 96 | E8: tinyNAS | F8: PatchTS | G8: needTS_valid | H8: 208 | I8: 42.254904 | J8: 23.53 | K8: 80.81 | L8: 0 | M8: 0 | N8: 0 | O8: 0 | P8: 0 | Q8: 0 | R8: 0 | S8: 0 | T8: 0 | U8: 0 | V8: 0 | W8: 0 | X8: 0 | Y8: 0 | Z8: 0 | AA8: 0 | AB8: 0 | AC8: 0 | AD8: 0 | AE8: 0 | AF8: 0 | AG8: 0 | AH8: 0 | AI8: 0 | AJ8: 57 | AK8: 0 | AL8: 9 | AM8: 0 | AN8: 9 | AO8: 0 | AP8: 0 | AQ8: 3 | AR8: 0 | AS8: 3 | AT8: 10 | AU8: 17 | AV8: 24 | AW8: 2 | AX8: 0 | AY8: 0 | AZ8: 0 | BA8: 0 | BB8: 0 | BC8: 0 | BD8: 0 | BE8: 3 | BF8: 0 | BG8: 0 | BH8: 0 | BI8: 0 | BJ8: 0 | BK8: 2 | BL8: 0 | BM8: 0 | BN8: 0 | BO8: 0 | BP8: 2 | BQ8: 0 | BR8: 0 | BS8: 0 | BT8: 0 | BU8: 1 | BV8: 28 | BW8: 3 | BX8: 0 | BY8: 0 | BZ8: 3 | CA8: 0 | CB8: 13 | CC8: 0 | CD8: 0 | CE8: 3 | CF8: 2 | CG8: 0 | CH8: 0 | CI8: 0 | CJ8: 1 | CK8: 1 | CL8: 0 | CM8: 0 | CN8: 6 | CO8: 6 | CP8: 0 | CQ8: 0 | CR8: 0 | CS8: 0 | CT8: 0 | CU8: 0 | CV8: 0 | CW8: 0 | CX8: 0 | CY8: 0 | CZ8: 0 | DA8: 0 | DB8: 0 | DC8: 0 | DD8: 0 | DE8: 0 | DF8: 0 | DG8: 0 | DH8: 0
A9: mbv2 | B9: MobileNet | C9: vm96 | D9: 96 | E9: tinyNAS | F9: PatchTS | G9: needTS_invalid | H9: 2325 | I9: 10.81391 | J9: 0 | K9: 85.23 | L9: 1557 | M9: 8 | N9: 0 | O9: 0 | P9: 0 | Q9: 0 | R9: 29 | S9: 0 | T9: 0 | U9: 0 | V9: 6 | W9: 0 | X9: 0 | Y9: 0 | Z9: 0 | AA9: 4 | AB9: 0 | AC9: 0 | AD9: 0 | AE9: 0 | AF9: 33 | AG9: 0 | AH9: 0 | AI9: 7 | AJ9: 346 | AK9: 0 | AL9: 24 | AM9: 31 | AN9: 42 | AO9: 14 | AP9: 0 | AQ9: 9 | AR9: 0 | AS9: 2 | AT9: 0 | AU9: 0 | AV9: 0 | AW9: 7 | AX9: 0 | AY9: 0 | AZ9: 0 | BA9: 0 | BB9: 0 | BC9: 0 | BD9: 49 | BE9: 3 | BF9: 3 | BG9: 0 | BH9: 1 | BI9: 0 | BJ9: 30 | BK9: 1 | BL9: 0 | BM9: 2 | BN9: 0 | BO9: 0 | BP9: 7 | BQ9: 0 | BR9: 0 | BS9: 0 | BT9: 0 | BU9: 14 | BV9: 38 | BW9: 2 | BX9: 2 | BY9: 0 | BZ9: 6 | CA9: 0 | CB9: 0 | CC9: 0 | CD9: 0 | CE9: 2 | CF9: 2 | CG9: 0 | CH9: 13 | CI9: 3 | CJ9: 6 | CK9: 0 | CL9: 0 | CM9: 0 | CN9: 14 | CO9: 4 | CP9: 0 | CQ9: 0 | CR9: 0 | CS9: 4 | CT9: 0 | CU9: 0 | CV9: 0 | CW9: 0 | CX9: 0 | CY9: 0 | CZ9: 0 | DA9: 0 | DB9: 0 | DC9: 0 | DD9: 0 | DE9: 0 | DF9: 0 | DG9: 0 | DH9: 0
A10: mbv2 | B10: MobileNet | C10: vm96 | D10: 96 | E10: tinyNAS | F10: PatchTS | G10: needTS_all | H10: 2533 | I10: 13.39572 | J10: 0 | K10: 85.23 | L10: 1557 | M10: 8 | N10: 0 | O10: 0 | P10: 0 | Q10: 0 | R10: 29 | S10: 0 | T10: 0 | U10: 0 | V10: 6 | W10: 0 | X10: 0 | Y10: 0 | Z10: 0 | AA10: 4 | AB10: 0 | AC10: 0 | AD10: 0 | AE10: 0 | AF10: 33 | AG10: 0 | AH10: 0 | AI10: 7 | AJ10: 403 | AK10: 0 | AL10: 33 | AM10: 31 | AN10: 51 | AO10: 14 | AP10: 0 | AQ10: 12 | AR10: 0 | AS10: 5 | AT10: 10 | AU10: 17 | AV10: 24 | AW10: 9 | AX10: 0 | AY10: 0 | AZ10: 0 | BA10: 0 | BB10: 0 | BC10: 0 | BD10: 49 | BE10: 6 | BF10: 3 | BG10: 0 | BH10: 1 | BI10: 0 | BJ10: 30 | BK10: 3 | BL10: 0 | BM10: 2 | BN10: 0 | BO10: 0 | BP10: 9 | BQ10: 0 | BR10: 0 | BS10: 0 | BT10: 0 | BU10: 15 | BV10: 66 | BW10: 5 | BX10: 2 | BY10: 0 | BZ10: 9 | CA10: 0 | CB10: 13 | CC10: 0 | CD10: 0 | CE10: 5 | CF10: 4 | CG10: 0 | CH10: 13 | CI10: 3 | CJ10: 7 | CK10: 1 | CL10: 0 | CM10: 0 | CN10: 20 | CO10: 10 | CP10: 0 | CQ10: 0 | CR10: 0 | CS10: 4 | CT10: 0 | CU10: 0 | CV10: 0 | CW10: 0 | CX10: 0 | CY10: 0 | CZ10: 0 | DA10: 0 | DB10: 0 | DC10: 0 | DD10: 0 | DE10: 0 | DF10: 0 | DG10: 0 | DH10: 0
A11: mbv2 | B11: MobileNet | C11: vm128 | D11: 128 | E11: ourTS | F11: DupNAS | G11: needTS_valid | H11: 1871 | I11: 63.441149 | J11: 19.86 | K11: 88 | L11: 0 | M11: 0 | N11: 0 | O11: 0 | P11: 0 | Q11: 0 | R11: 0 | S11: 0 | T11: 0 | U11: 0 | V11: 0 | W11: 0 | X11: 0 | Y11: 0 | Z11: 0 | AA11: 0 | AB11: 0 | AC11: 0 | AD11: 0 | AE11: 0 | AF11: 10 | AG11: 0 | AH11: 0 | AI11: 9 | AJ11: 40 | AK11: 2 | AL11: 3 | AM11: 6 | AN11: 86 | AO11: 6 | AP11: 0 | AQ11: 70 | AR11: 0 | AS11: 0 | AT11: 5 | AU11: 0 | AV11: 0 | AW11: 2 | AX11: 0 | AY11: 56 | AZ11: 0 | BA11: 81 | BB11: 0 | BC11: 17 | BD11: 19 | BE11: 0 | BF11: 0 | BG11: 55 | BH11: 12 | BI11: 0 | BJ11: 72 | BK11: 6 | BL11: 9 | BM11: 0 | BN11: 0 | BO11: 0 | BP11: 0 | BQ11: 0 | BR11: 0 | BS11: 0 | BT11: 49 | BU11: 23 | BV11: 117 | BW11: 24 | BX11: 83 | BY11: 6 | BZ11: 0 | CA11: 0 | CB11: 0 | CC11: 5 | CD11: 0 | CE11: 17 | CF11: 125 | CG11: 122 | CH11: 89 | CI11: 26 | CJ11: 46 | CK11: 4 | CL11: 71 | CM11: 37 | CN11: 84 | CO11: 55 | CP11: 108 | CQ11: 2 | CR11: 5 | CS11: 148 | CT11: 21 | CU11: 0 | CV11: 38 | CW11: 0 | CX11: 0 | CY11: 0 | CZ11: 0 | DA11: 0 | DB11: 0 | DC11: 0 | DD11: 0 | DE11: 0 | DF11: 0 | DG11: 0 | DH11: 0
A12: mbv2 | B12: MobileNet | C12: vm128 | D12: 128 | E12: ourTS | F12: DupNAS | G12: needTS_invalid | H12: 457 | I12: 59.8814 | J12: 0 | K12: 88 | L12: 125 | M12: 0 | N12: 0 | O12: 0 | P12: 0 | Q12: 0 | R12: 0 | S12: 0 | T12: 0 | U12: 0 | V12: 0 | W12: 0 | X12: 0 | Y12: 0 | Z12: 0 | AA12: 0 | AB12: 0 | AC12: 0 | AD12: 0 | AE12: 0 | AF12: 0 | AG12: 0 | AH12: 0 | AI12: 0 | AJ12: 0 | AK12: 0 | AL12: 0 | AM12: 0 | AN12: 0 | AO12: 0 | AP12: 0 | AQ12: 0 | AR12: 0 | AS12: 0 | AT12: 0 | AU12: 0 | AV12: 0 | AW12: 0 | AX12: 0 | AY12: 0 | AZ12: 0 | BA12: 0 | BB12: 0 | BC12: 0 | BD12: 0 | BE12: 0 | BF12: 0 | BG12: 0 | BH12: 0 | BI12: 0 | BJ12: 0 | BK12: 0 | BL12: 0 | BM12: 0 | BN12: 10 | BO12: 0 | BP12: 0 | BQ12: 0 | BR12: 0 | BS12: 0 | BT12: 0 | BU12: 0 | BV12: 0 | BW12: 0 | BX12: 0 | BY12: 7 | BZ12: 0 | CA12: 0 | CB12: 0 | CC12: 0 | CD12: 0 | CE12: 0 | CF12: 0 | CG12: 0 | CH12: 0 | CI12: 0 | CJ12: 6 | CK12: 65 | CL12: 0 | CM12: 0 | CN12: 0 | CO12: 0 | CP12: 93 | CQ12: 6 | CR12: 0 | CS12: 0 | CT12: 0 | CU12: 0 | CV12: 145 | CW12: 0 | CX12: 0 | CY12: 0 | CZ12: 0 | DA12: 0 | DB12: 0 | DC12: 0 | DD12: 0 | DE12: 0 | DF12: 0 | DG12: 0 | DH12: 0
A13: mbv2 | B13: MobileNet | C13: vm128 | D13: 128 | E13: ourTS | F13: DupNAS | G13: needTS_all | H13: 2328 | I13: 62.74235 | J13: 0 | K13: 88 | L13: 125 | M13: 0 | N13: 0 | O13: 0 | P13: 0 | Q13: 0 | R13: 0 | S13: 0 | T13: 0 | U13: 0 | V13: 0 | W13: 0 | X13: 0 | Y13: 0 | Z13: 0 | AA13: 0 | AB13: 0 | AC13: 0 | AD13: 0 | AE13: 0 | AF13: 10 | AG13: 0 | AH13: 0 | AI13: 9 | AJ13: 40 | AK13: 2 | AL13: 3 | AM13: 6 | AN13: 86 | AO13: 6 | AP13: 0 | AQ13: 70 | AR13: 0 | AS13: 0 | AT13: 5 | AU13: 0 | AV13: 0 | AW13: 2 | AX13: 0 | AY13: 56 | AZ13: 0 | BA13: 81 | BB13: 0 | BC13: 17 | BD13: 19 | BE13: 0 | BF13: 0 | BG13: 55 | BH13: 12 | BI13: 0 | BJ13: 72 | BK13: 6 | BL13: 9 | BM13: 0 | BN13: 10 | BO13: 0 | BP13: 0 | BQ13: 0 | BR13: 0 | BS13: 0 | BT13: 49 | BU13: 23 | BV13: 117 | BW13: 24 | BX13: 83 | BY13: 13 | BZ13: 0 | CA13: 0 | CB13: 0 | CC13: 5 | CD13: 0 | CE13: 17 | CF13: 125 | CG13: 122 | CH13: 89 | CI13: 26 | CJ13: 52 | CK13: 69 | CL13: 71 | CM13: 37 | CN13: 84 | CO13: 55 | CP13: 201 | CQ13: 8 | CR13: 5 | CS13: 148 | CT13: 21 | CU13: 0 | CV13: 183 | CW13: 0 | CX13: 0 | CY13: 0 | CZ13: 0 | DA13: 0 | DB13: 0 | DC13: 0 | DD13: 0 | DE13: 0 | DF13: 0 | DG13: 0 | DH13: 0
... A52: shuffle | B52: ShuffleNet | C52: vm256 | D52: 256 | E52: tinyTS | F52: TinyTS | G52: needTS_all | H52: 445 | I52: 19.305798 | J52: 0 | K52: 33.07 | L52: 184 | M52: 0 | N52: 0 | O52: 0 | P52: 0 | Q52: 0 | R52: 0 | S52: 0 | T52: 0 | U52: 0 | V52: 0 | W52: 0 | X52: 0 | Y52: 0 | Z52: 0 | AA52: 0 | AB52: 0 | AC52: 0 | AD52: 0 | AE52: 0 | AF52: 0 | AG52: 0 | AH52: 0 | AI52: 0 | AJ52: 0 | AK52: 0 | AL52: 0 | AM52: 0 | AN52: 0 | AO52: 0 | AP52: 0 | AQ52: 0 | AR52: 53 | AS52: 208 | AT52: 0 | AU52: 0 | AV52: 0 | AW52: 0 | AX52: 0 | AY52: 0 | AZ52: 0 | BA52: 0 | BB52: 0 | BC52: 0 | BD52: 0 | BE52: 0 | BF52: 0 | BG52: 0 | BH52: 0 | BI52: 0 | BJ52: 0 | BK52: 0 | BL52: 0 | BM52: 0 | BN52: 0 | BO52: 0 | BP52: 0 | BQ52: 0 | BR52: 0 | BS52: 0 | BT52: 0 | BU52: 0 | BV52: 0 | BW52: 0 | BX52: 0 | BY52: 0 | BZ52: 0 | CA52: 0 | CB52: 0 | CC52: 0 | CD52: 0 | CE52: 0 | CF52: 0 | CG52: 0 | CH52: 0 | CI52: 0 | CJ52: 0 | CK52: 0 | CL52: 0 | CM52: 0 | CN52: 0 | CO52: 0 | CP52: 0 | CQ52: 0 | CR52: 0 | CS52: 0 | CT52: 0 | CU52: 0 | CV52: 0 | CW52: 0 | CX52: 0 | CY52: 0 | CZ52: 0 | DA52: 0 | DB52: 0 | DC52: 0 | DD52: 0 | DE52: 0 | DF52: 0 | DG52: 0 | DH52: 0
A53: shuffle | B53: ShuffleNet | C53: vm256 | D53: 256 | E53: tinyNAS | F53: PatchTS | G53: needTS_valid | H53: 0 | L53: 0 | M53: 0 | N53: 0 | O53: 0 | P53: 0 | Q53: 0 | R53: 0 | S53: 0 | T53: 0 | U53: 0 | V53: 0 | W53: 0 | X53: 0 | Y53: 0 | Z53: 0 | AA53: 0 | AB53: 0 | AC53: 0 | AD53: 0 | AE53: 0 | AF53: 0 | AG53: 0 | AH53: 0 | AI53: 0 | AJ53: 0 | AK53: 0 | AL53: 0 | AM53: 0 | AN53: 0 | AO53: 0 | AP53: 0 | AQ53: 0 | AR53: 0 | AS53: 0 | AT53: 0 | AU53: 0 | AV53: 0 | AW53: 0 | AX53: 0 | AY53: 0 | AZ53: 0 | BA53: 0 | BB53: 0 | BC53: 0 | BD53: 0 | BE53: 0 | BF53: 0 | BG53: 0 | BH53: 0 | BI53: 0 | BJ53: 0 | BK53: 0 | BL53: 0 | BM53: 0 | BN53: 0 | BO53: 0 | BP53: 0 | BQ53: 0 | BR53: 0 | BS53: 0 | BT53: 0 | BU53: 0 | BV53: 0 | BW53: 0 | BX53: 0 | BY53: 0 | BZ53: 0 | CA53: 0 | CB53: 0 | CC53: 0 | CD53: 0 | CE53: 0 | CF53: 0 | CG53: 0 | CH53: 0 | CI53: 0 | CJ53: 0 | CK53: 0 | CL53: 0 | CM53: 0 | CN53: 0 | CO53: 0 | CP53: 0 | CQ53: 0 | CR53: 0 | CS53: 0 | CT53: 0 | CU53: 0 | CV53: 0 | CW53: 0 | CX53: 0 | CY53: 0 | CZ53: 0 | DA53: 0 | DB53: 0 | DC53: 0 | DD53: 0 | DE53: 0 | DF53: 0 | DG53: 0 | DH53: 0
A54: shuffle | B54: ShuffleNet | C54: vm256 | D54: 256 | E54: tinyNAS | F54: PatchTS | G54: needTS_invalid | H54: 445 | I54: 0 | J54: 0 | K54: 0 | L54: 445 | M54: 0 | N54: 0 | O54: 0 | P54: 0 | Q54: 0 | R54: 0 | S54: 0 | T54: 0 | U54: 0 | V54: 0 | W54: 0 | X54: 0 | Y54: 0 | Z54: 0 | AA54: 0 | AB54: 0 | AC54: 0 | AD54: 0 | AE54: 0 | AF54: 0 | AG54: 0 | AH54: 0 | AI54: 0 | AJ54: 0 | AK54: 0 | AL54: 0 | AM54: 0 | AN54: 0 | AO54: 0 | AP54: 0 | AQ54: 0 | AR54: 0 | AS54: 0 | AT54: 0 | AU54: 0 | AV54: 0 | AW54: 0 | AX54: 0 | AY54: 0 | AZ54: 0 | BA54: 0 | BB54: 0 | BC54: 0 | BD54: 0 | BE54: 0 | BF54: 0 | BG54: 0 | BH54: 0 | BI54: 0 | BJ54: 0 | BK54: 0 | BL54: 0 | BM54: 0 | BN54: 0 | BO54: 0 | BP54: 0 | BQ54: 0 | BR54: 0 | BS54: 0 | BT54: 0 | BU54: 0 | BV54: 0 | BW54: 0 | BX54: 0 | BY54: 0 | BZ54: 0 | CA54: 0 | CB54: 0 | CC54: 0 | CD54: 0 | CE54: 0 | CF54: 0 | CG54: 0 | CH54: 0 | CI54: 0 | CJ54: 0 | CK54: 0 | CL54: 0 | CM54: 0 | CN54: 0 | CO54: 0 | CP54: 0 | CQ54: 0 | CR54: 0 | CS54: 0 | CT54: 0 | CU54: 0 | CV54: 0 | CW54: 0 | CX54: 0 | CY54: 0 | CZ54: 0 | DA54: 0 | DB54: 0 | DC54: 0 | DD54: 0 | DE54: 0 | DF54: 0 | DG54: 0 | DH54: 0
A55: shuffle | B55: ShuffleNet | C55: vm256 | D55: 256 | E55: tinyNAS | F55: PatchTS | G55: needTS_all | H55: 445 | I55: 0 | J55: 0 | K55: 0 | L55: 445 | M55: 0 | N55: 0 | O55: 0 | P55: 0 | Q55: 0 | R55: 0 | S55: 0 | T55: 0 | U55: 0 | V55: 0 | W55: 0 | X55: 0 | Y55: 0 | Z55: 0 | AA55: 0 | AB55: 0 | AC55: 0 | AD55: 0 | AE55: 0 | AF55: 0 | AG55: 0 | AH55: 0 | AI55: 0 | AJ55: 0 | AK55: 0 | AL55: 0 | AM55: 0 | AN55: 0 | AO55: 0 | AP55: 0 | AQ55: 0 | AR55: 0 | AS55: 0 | AT55: 0 | AU55: 0 | AV55: 0 | AW55: 0 | AX55: 0 | AY55: 0 | AZ55: 0 | BA55: 0 | BB55: 0 | BC55: 0 | BD55: 0 | BE55: 0 | BF55: 0 | BG55: 0 | BH55: 0 | BI55: 0 | BJ55: 0 | BK55: 0 | BL55: 0 | BM55: 0 | BN55: 0 | BO55: 0 | BP55: 0 | BQ55: 0 | BR55: 0 | BS55: 0 | BT55: 0 | BU55: 0 | BV55: 0 | BW55: 0 | BX55: 0 | BY55: 0 | BZ55: 0 | CA55: 0 | CB55: 0 | CC55: 0 | CD55: 0 | CE55: 0 | CF55: 0 | CG55: 0 | CH55: 0 | CI55: 0 | CJ55: 0 | CK55: 0 | CL55: 0 | CM55: 0 | CN55: 0 | CO55: 0 | CP55: 0 | CQ55: 0 | CR55: 0 | CS55: 0 | CT55: 0 | CU55: 0 | CV55: 0 | CW55: 0 | CX55: 0 | CY55: 0 | CZ55: 0 | DA55: 0 | DB55: 0 | DC55: 0 | DD55: 0 | DE55: 0 | DF55: 0 | DG55: 0 | DH55: 0
A56: incept | B56: InceptionNet | C56: vm96 | D56: 96 | E56: ourTS | F56: DupNAS | G56: needTS_valid | H56: 340 | I56: 45.853029 | J56: 13.64 | K56: 57.58 | L56: 0 | M56: 0 | N56: 0 | O56: 0 | P56: 0 | Q56: 0 | R56: 0 | S56: 0 | T56: 0 | U56: 0 | V56: 0 | W56: 0 | X56: 0 | Y56: 0 | Z56: 13 | AA56: 0 | AB56: 3 | AC56: 0 | AD56: 0 | AE56: 0 | AF56: 0 | AG56: 0 | AH56: 0 | AI56: 0 | AJ56: 0 | AK56: 0 | AL56: 0 | AM56: 86 | AN56: 0 | AO56: 0 | AP56: 0 | AQ56: 0 | AR56: 0 | AS56: 0 | AT56: 0 | AU56: 0 | AV56: 0 | AW56: 0 | AX56: 0 | AY56: 0 | AZ56: 0 | BA56: 0 | BB56: 0 | BC56: 0 | BD56: 0 | BE56: 0 | BF56: 0 | BG56: 0 | BH56: 0 | BI56: 0 | BJ56: 52 | BK56: 10 | BL56: 0 | BM56: 0 | BN56: 0 | BO56: 23 | BP56: 131 | BQ56: 0 | BR56: 22 | BS56: 0 | BT56: 0 | BU56: 0 | BV56: 0 | BW56: 0 | BX56: 0 | BY56: 0 | BZ56: 0 | CA56: 0 | CB56: 0 | CC56: 0 | CD56: 0 | CE56: 0 | CF56: 0 | CG56: 0 | CH56: 0 | CI56: 0 | CJ56: 0 | CK56: 0 | CL56: 0 | CM56: 0 | CN56: 0 | CO56: 0 | CP56: 0 | CQ56: 0 | CR56: 0 | CS56: 0 | CT56: 0 | CU56: 0 | CV56: 0 | CW56: 0 | CX56: 0 | CY56: 0 | CZ56: 0 | DA56: 0 | DB56: 0 | DC56: 0 | DD56: 0 | DE56: 0 | DF56: 0 | DG56: 0 | DH56: 0
A57: incept | B57: InceptionNet | C57: vm96 | D57: 96 | E57: ourTS | F57: DupNAS | G57: needTS_invalid | H57: 1657 | I57: 6.1360229 | J57: 0 | K57: 40.35 | L57: 1103 | M57: 0 | N57: 0 | O57: 0 | P57: 0 | Q57: 0 | R57: 0 | S57: 0 | T57: 224 | U57: 0 | V57: 0 | W57: 46 | X57: 10 | Y57: 0 | Z57: 0 | AA57: 0 | AB57: 0 | AC57: 0 | AD57: 0 | AE57: 0 | AF57: 0 | AG57: 0 | AH57: 0 | AI57: 13 | AJ57: 0 | AK57: 5 | AL57: 0 | AM57: 220 | AN57: 0 | AO57: 0 | AP57: 0 | AQ57: 7 | AR57: 0 | AS57: 20 | AT57: 0 | AU57: 0 | AV57: 0 | AW57: 0 | AX57: 0 | AY57: 0 | AZ57: 9 | BA57: 0 | BB57: 0 | BC57: 0 | BD57: 0 | BE57: 0 | BF57: 0 | BG57: 0 | BH57: 0 | BI57: 0 | BJ57: 0 | BK57: 0 | BL57: 0 | BM57: 0 | BN57: 0 | BO57: 0 | BP57: 0 | BQ57: 0 | BR57: 0 | BS57: 0 | BT57: 0 | BU57: 0 | BV57: 0 | BW57: 0 | BX57: 0 | BY57: 0 | BZ57: 0 | CA57: 0 | CB57: 0 | CC57: 0 | CD57: 0 | CE57: 0 | CF57: 0 | CG57: 0 | CH57: 0 | CI57: 0 | CJ57: 0 | CK57: 0 | CL57: 0 | CM57: 0 | CN57: 0 | CO57: 0 | CP57: 0 | CQ57: 0 | CR57: 0 | CS57: 0 | CT57: 0 | CU57: 0 | CV57: 0 | CW57: 0 | CX57: 0 | CY57: 0 | CZ57: 0 | DA57: 0 | DB57: 0 | DC57: 0 | DD57: 0 | DE57: 0 | DF57: 0 | DG57: 0 | DH57: 0
A58: incept | B58: InceptionNet | C58: vm96 | D58: 96 | E58: ourTS | F58: DupNAS | G58: needTS_all | H58: 1997 | I58: 12.898057 | J58: 0 | K58: 57.58 | L58: 1103 | M58: 0 | N58: 0 | O58: 0 | P58: 0 | Q58: 0 | R58: 0 | S58: 0 | T58: 224 | U58: 0 | V58: 0 | W58: 46 | X58: 10 | Y58: 0 | Z58: 13 | AA58: 0 | AB58: 3 | AC58: 0 | AD58: 0 | AE58: 0 | AF58: 0 | AG58: 0 | AH58: 0 | AI58: 13 | AJ58: 0 | AK58: 5 | AL58: 0 | AM58: 306 | AN58: 0 | AO58: 0 | AP58: 0 | AQ58: 7 | AR58: 0 | AS58: 20 | AT58: 0 | AU58: 0 | AV58: 0 | AW58: 0 | AX58: 0 | AY58: 0 | AZ58: 9 | BA58: 0 | BB58: 0 | BC58: 0 | BD58: 0 | BE58: 0 | BF58: 0 | BG58: 0 | BH58: 0 | BI58: 0 | BJ58: 52 | BK58: 10 | BL58: 0 | BM58: 0 | BN58: 0 | BO58: 23 | BP58: 131 | BQ58: 0 | BR58: 22 | BS58: 0 | BT58: 0 | BU58: 0 | BV58: 0 | BW58: 0 | BX58: 0 | BY58: 0 | BZ58: 0 | CA58: 0 | CB58: 0 | CC58: 0 | CD58: 0 | CE58: 0 | CF58: 0 | CG58: 0 | CH58: 0 | CI58: 0 | CJ58: 0 | CK58: 0 | CL58: 0 | CM58: 0 | CN58: 0 | CO58: 0 | CP58: 0 | CQ58: 0 | CR58: 0 | CS58: 0 | CT58: 0 | CU58: 0 | CV58: 0 | CW58: 0 | CX58: 0 | CY58: 0 | CZ58: 0 | DA58: 0 | DB58: 0 | DC58: 0 | DD58: 0 | DE58: 0 | DF58: 0 | DG58: 0 | DH58: 0
A59: incept | B59: InceptionNet | C59: vm96 | D59: 96 | E59: tinyTS | F59: TinyTS | G59: needTS_valid | H59: 102 | I59: 26.932353 | J59: 15.79 | K59: 27.27 | L59: 0 | M59: 0 | N59: 0 | O59: 0 | P59: 0 | Q59: 0 | R59: 0 | S59: 0 | T59: 0 | U59: 0 | V59: 0 | W59: 0 | X59: 0 | Y59: 0 | Z59: 0 | AA59: 0 | AB59: 3 | AC59: 0 | AD59: 0 | AE59: 0 | AF59: 0 | AG59: 0 | AH59: 0 | AI59: 0 | AJ59: 0 | AK59: 0 | AL59: 0 | AM59: 99 | AN59: 0 | AO59: 0 | AP59: 0 | AQ59: 0 | AR59: 0 | AS59: 0 | AT59: 0 | AU59: 0 | AV59: 0 | AW59: 0 | AX59: 0 | AY59: 0 | AZ59: 0 | BA59: 0 | BB59: 0 | BC59: 0 | BD59: 0 | BE59: 0 | BF59: 0 | BG59: 0 | BH59: 0 | BI59: 0 | BJ59: 0 | BK59: 0 | BL59: 0 | BM59: 0 | BN59: 0 | BO59: 0 | BP59: 0 | BQ59: 0 | BR59: 0 | BS59: 0 | BT59: 0 | BU59: 0 | BV59: 0 | BW59: 0 | BX59: 0 | BY59: 0 | BZ59: 0 | CA59: 0 | CB59: 0 | CC59: 0 | CD59: 0 | CE59: 0 | CF59: 0 | CG59: 0 | CH59: 0 | CI59: 0 | CJ59: 0 | CK59: 0 | CL59: 0 | CM59: 0 | CN59: 0 | CO59: 0 | CP59: 0 | CQ59: 0 | CR59: 0 | CS59: 0 | CT59: 0 | CU59: 0 | CV59: 0 | CW59: 0 | CX59: 0 | CY59: 0 | CZ59: 0 | DA59: 0 | DB59: 0 | DC59: 0 | DD59: 0 | DE59: 0 | DF59: 0 | DG59: 0 | DH59: 0
A60: incept | B60: InceptionNet | C60: vm96 | D60: 96 | E60: tinyTS | F60: TinyTS | G60: needTS_invalid | H60: 1895 | I60: 15.006158 | J60: 0 | K60: 27.27 | L60: 750 | M60: 0 | N60: 0 | O60: 88 | P60: 0 | Q60: 0 | R60: 0 | S60: 0 | T60: 0 | U60: 0 | V60: 0 | W60: 0 | X60: 0 | Y60: 0 | Z60: 0 | AA60: 0 | AB60: 57 | AC60: 0 | AD60: 0 | AE60: 0 | AF60: 0 | AG60: 0 | AH60: 0 | AI60: 0 | AJ60: 0 | AK60: 0 | AL60: 0 | AM60: 1000 | AN60: 0 | AO60: 0 | AP60: 0 | AQ60: 0 | AR60: 0 | AS60: 0 | AT60: 0 | AU60: 0 | AV60: 0 | AW60: 0 | AX60: 0 | AY60: 0 | AZ60: 0 | BA60: 0 | BB60: 0 | BC60: 0 | BD60: 0 | BE60: 0 | BF60: 0 | BG60: 0 | BH60: 0 | BI60: 0 | BJ60: 0 | BK60: 0 | BL60: 0 | BM60: 0 | BN60: 0 | BO60: 0 | BP60: 0 | BQ60: 0 | BR60: 0 | BS60: 0 | BT60: 0 | BU60: 0 | BV60: 0 | BW60: 0 | BX60: 0 | BY60: 0 | BZ60: 0 | CA60: 0 | CB60: 0 | CC60: 0 | CD60: 0 | CE60: 0 | CF60: 0 | CG60: 0 | CH60: 0 | CI60: 0 | CJ60: 0 | CK60: 0 | CL60: 0 | CM60: 0 | CN60: 0 | CO60: 0 | CP60: 0 | CQ60: 0 | CR60: 0 | CS60: 0 | CT60: 0 | CU60: 0 | CV60: 0 | CW60: 0 | CX60: 0 | CY60: 0 | CZ60: 0 | DA60: 0 | DB60: 0 | DC60: 0 | DD60: 0 | DE60: 0 | DF60: 0 | DG60: 0 | DH60: 0
A61: incept | B61: InceptionNet | C61: vm96 | D61: 96 | E61: tinyTS | F61: TinyTS | G61: needTS_all | H61: 1997 | I61: 15.615308 | J61: 0 | K61: 27.27 | L61: 750 | M61: 0 | N61: 0 | O61: 88 | P61: 0 | Q61: 0 | R61: 0 | S61: 0 | T61: 0 | U61: 0 | V61: 0 | W61: 0 | X61: 0 | Y61: 0 | Z61: 0 | AA61: 0 | AB61: 60 | AC61: 0 | AD61: 0 | AE61: 0 | AF61: 0 | AG61: 0 | AH61: 0 | AI61: 0 | AJ61: 0 | AK61: 0 | AL61: 0 | AM61: 1099 | AN61: 0 | AO61: 0 | AP61: 0 | AQ61: 0 | AR61: 0 | AS61: 0 | AT61: 0 | AU61: 0 | AV61: 0 | AW61: 0 | AX61: 0 | AY61: 0 | AZ61: 0 | BA61: 0 | BB61: 0 | BC61: 0 | BD61: 0 | BE61: 0 | BF61: 0 | BG61: 0 | BH61: 0 | BI61: 0 | BJ61: 0 | BK61: 0 | BL61: 0 | BM61: 0 | BN61: 0 | BO61: 0 | BP61: 0 | BQ61: 0 | BR61: 0 | BS61: 0 | BT61: 0 | BU61: 0 | BV61: 0 | BW61: 0 | BX61: 0 | BY61: 0 | BZ61: 0 | CA61: 0 | CB61: 0 | CC61: 0 | CD61: 0 | CE61: 0 | CF61: 0 | CG61: 0 | CH61: 0 | CI61: 0 | CJ61: 0 | CK61: 0 | CL61: 0 | CM61: 0 | CN61: 0 | CO61: 0 | CP61: 0 | CQ61: 0 | CR61: 0 | CS61: 0 | CT61: 0 | CU61: 0 | CV61: 0 | CW61: 0 | CX61: 0 | CY61: 0 | CZ61: 0 | DA61: 0 | DB61: 0 | DC61: 0 | DD61: 0 | DE61: 0 | DF61: 0 | DG61: 0 | DH61: 0
A62: incept | B62: InceptionNet | C62: vm96 | D62: 96 | E62: tinyNAS | F62: PatchTS | G62: needTS_valid | H62: 224 | I62: 22.934062 | J62: 14.58 | K62: 28.65 | L62: 0 | M62: 0 | N62: 0 | O62: 0 | P62: 0 | Q62: 0 | R62: 0 | S62: 0 | T62: 0 | U62: 0 | V62: 0 | W62: 0 | X62: 0 | Y62: 0 | Z62: 0 | AA62: 45 | AB62: 0 | AC62: 0 | AD62: 0 | AE62: 31 | AF62: 0 | AG62: 0 | AH62: 0 | AI62: 0 | AJ62: 76 | AK62: 0 | AL62: 0 | AM62: 0 | AN62: 0 | AO62: 72 | AP62: 0 | AQ62: 0 | AR62: 0 | AS62: 0 | AT62: 0 | AU62: 0 | AV62: 0 | AW62: 0 | AX62: 0 | AY62: 0 | AZ62: 0 | BA62: 0 | BB62: 0 | BC62: 0 | BD62: 0 | BE62: 0 | BF62: 0 | BG62: 0 | BH62: 0 | BI62: 0 | BJ62: 0 | BK62: 0 | BL62: 0 | BM62: 0 | BN62: 0 | BO62: 0 | BP62: 0 | BQ62: 0 | BR62: 0 | BS62: 0 | BT62: 0 | BU62: 0 | BV62: 0 | BW62: 0 | BX62: 0 | BY62: 0 | BZ62: 0 | CA62: 0 | CB62: 0 | CC62: 0 | CD62: 0 | CE62: 0 | CF62: 0 | CG62: 0 | CH62: 0 | CI62: 0 | CJ62: 0 | CK62: 0 | CL62: 0 | CM62: 0 | CN62: 0 | CO62: 0 | CP62: 0 | CQ62: 0 | CR62: 0 | CS62: 0 | CT62: 0 | CU62: 0 | CV62: 0 | CW62: 0 | CX62: 0 | CY62: 0 | CZ62: 0 | DA62: 0 | DB62: 0 | DC62: 0 | DD62: 0 | DE62: 0 | DF62: 0 | DG62: 0 | DH62: 0
A63: incept | B63: InceptionNet | C63: vm96 | D63: 96 | E63: tinyNAS | F63: PatchTS | G63: needTS_invalid | H63: 1773 | I63: 4.4212916 | J63: 0 | K63: 44.01 | L63: 1562 | M63: 0 | N63: 0 | O63: 0 | P63: 0 | Q63: 0 | R63: 0 | S63: 0 | T63: 0 | U63: 0 | V63: 0 | W63: 0 | X63: 0 | Y63: 0 | Z63: 0 | AA63: 0 | AB63: 0 | AC63: 0 | AD63: 0 | AE63: 0 | AF63: 0 | AG63: 0 | AH63: 0 | AI63: 0 | AJ63: 0 | AK63: 5 | AL63: 0 | AM63: 0 | AN63: 0 | AO63: 0 | AP63: 0 | AQ63: 68 | AR63: 18 | AS63: 0 | AT63: 0 | AU63: 0 | AV63: 23 | AW63: 0 | AX63: 0 | AY63: 0 | AZ63: 24 | BA63: 0 | BB63: 0 | BC63: 0 | BD63: 73 | BE63: 0 | BF63: 0 | BG63: 0 | BH63: 0 | BI63: 0 | BJ63: 0 | BK63: 0 | BL63: 0 | BM63: 0 | BN63: 0 | BO63: 0 | BP63: 0 | BQ63: 0 | BR63: 0 | BS63: 0 | BT63: 0 | BU63: 0 | BV63: 0 | BW63: 0 | BX63: 0 | BY63: 0 | BZ63: 0 | CA63: 0 | CB63: 0 | CC63: 0 | CD63: 0 | CE63: 0 | CF63: 0 | CG63: 0 | CH63: 0 | CI63: 0 | CJ63: 0 | CK63: 0 | CL63: 0 | CM63: 0 | CN63: 0 | CO63: 0 | CP63: 0 | CQ63: 0 | CR63: 0 | CS63: 0 | CT63: 0 | CU63: 0 | CV63: 0 | CW63: 0 | CX63: 0 | CY63: 0 | CZ63: 0 | DA63: 0 | DB63: 0 | DC63: 0 | DD63: 0 | DE63: 0 | DF63: 0 | DG63: 0 | DH63: 0
A64: incept | B64: InceptionNet | C64: vm96 | D64: 96 | E64: tinyNAS | F64: PatchTS | G64: needTS_all | H64: 1997 | I64: 6.4978368 | J64: 0 | K64: 44.01 | L64: 1562 | M64: 0 | N64: 0 | O64: 0 | P64: 0 | Q64: 0 | R64: 0 | S64: 0 | T64: 0 | U64: 0 | V64: 0 | W64: 0 | X64: 0 | Y64: 0 | Z64: 0 | AA64: 45 | AB64: 0 | AC64: 0 | AD64: 0 | AE64: 31 | AF64: 0 | AG64: 0 | AH64: 0 | AI64: 0 | AJ64: 76 | AK64: 5 | AL64: 0 | AM64: 0 | AN64: 0 | AO64: 72 | AP64: 0 | AQ64: 68 | AR64: 18 | AS64: 0 | AT64: 0 | AU64: 0 | AV64: 23 | AW64: 0 | AX64: 0 | AY64: 0 | AZ64: 24 | BA64: 0 | BB64: 0 | BC64: 0 | BD64: 73 | BE64: 0 | BF64: 0 | BG64: 0 | BH64: 0 | BI64: 0 | BJ64: 0 | BK64: 0 | BL64: 0 | BM64: 0 | BN64: 0 | BO64: 0 | BP64: 0 | BQ64: 0 | BR64: 0 | BS64: 0 | BT64: 0 | BU64: 0 | BV64: 0 | BW64: 0 | BX64: 0 | BY64: 0 | BZ64: 0 | CA64: 0 | CB64: 0 | CC64: 0 | CD64: 0 | CE64: 0 | CF64: 0 | CG64: 0 | CH64: 0 | CI64: 0 | CJ64: 0 | CK64: 0 | CL64: 0 | CM64: 0 | CN64: 0 | CO64: 0 | CP64: 0 | CQ64: 0 | CR64: 0 | CS64: 0 | CT64: 0 | CU64: 0 | CV64: 0 | CW64: 0 | CX64: 0 | CY64: 0 | CZ64: 0 | DA64: 0 | DB64: 0 | DC64: 0 | DD64: 0 | DE64: 0 | DF64: 0 | DG64: 0 | DH64: 0
A65: incept | B65: InceptionNet | C65: vm128 | D65: 128 | E65: ourTS | F65: DupNAS | G65: needTS_valid | H65: 522 | I65: 33.594444 | J65: 12.28 | K65: 57.58 | L65: 0 | M65: 0 | N65: 0 | O65: 0 | P65: 0 | Q65: 0 | R65: 0 | S65: 0 | T65: 0 | U65: 0 | V65: 0 | W65: 0 | X65: 13 | Y65: 0 | Z65: 18 | AA65: 0 | AB65: 0 | AC65: 0 | AD65: 0 | AE65: 0 | AF65: 0 | AG65: 0 | AH65: 0 | AI65: 0 | AJ65: 20 | AK65: 0 | AL65: 0 | AM65: 187 | AN65: 0 | AO65: 0 | AP65: 0 | AQ65: 0 | AR65: 0 | AS65: 0 | AT65: 0 | AU65: 0 | AV65: 0 | AW65: 10 | AX65: 206 | AY65: 0 | AZ65: 0 | BA65: 0 | BB65: 0 | BC65: 0 | BD65: 0 | BE65: 22 | BF65: 0 | BG65: 10 | BH65: 0 | BI65: 0 | BJ65: 0 | BK65: 0 | BL65: 0 | BM65: 9 | BN65: 0 | BO65: 16 | BP65: 0 | BQ65: 0 | BR65: 11 | BS65: 0 | BT65: 0 | BU65: 0 | BV65: 0 | BW65: 0 | BX65: 0 | BY65: 0 | BZ65: 0 | CA65: 0 | CB65: 0 | CC65: 0 | CD65: 0 | CE65: 0 | CF65: 0 | CG65: 0 | CH65: 0 | CI65: 0 | CJ65: 0 | CK65: 0 | CL65: 0 | CM65: 0 | CN65: 0 | CO65: 0 | CP65: 0 | CQ65: 0 | CR65: 0 | CS65: 0 | CT65: 0 | CU65: 0 | CV65: 0 | CW65: 0 | CX65: 0 | CY65: 0 | CZ65: 0 | DA65: 0 | DB65: 0 | DC65: 0 | DD65: 0 | DE65: 0 | DF65: 0 | DG65: 0 | DH65: 0
... A79: incept | B79: InceptionNet | C79: vm256 | D79: 256 | E79: tinyTS | F79: TinyTS | G79: needTS_all | H79: 981 | I79: 22.068869 | J79: 0 | K79: 27.27 | L79: 177 | M79: 0 | N79: 0 | O79: 0 | P79: 0 | Q79: 0 | R79: 0 | S79: 0 | T79: 0 | U79: 0 | V79: 0 | W79: 0 | X79: 0 | Y79: 0 | Z79: 0 | AA79: 0 | AB79: 24 | AC79: 0 | AD79: 0 | AE79: 0 | AF79: 0 | AG79: 0 | AH79: 0 | AI79: 0 | AJ79: 0 | AK79: 0 | AL79: 0 | AM79: 780 | AN79: 0 | AO79: 0 | AP79: 0 | AQ79: 0 | AR79: 0 | AS79: 0 | AT79: 0 | AU79: 0 | AV79: 0 | AW79: 0 | AX79: 0 | AY79: 0 | AZ79: 0 | BA79: 0 | BB79: 0 | BC79: 0 | BD79: 0 | BE79: 0 | BF79: 0 | BG79: 0 | BH79: 0 | BI79: 0 | BJ79: 0 | BK79: 0 | BL79: 0 | BM79: 0 | BN79: 0 | BO79: 0 | BP79: 0 | BQ79: 0 | BR79: 0 | BS79: 0 | BT79: 0 | BU79: 0 | BV79: 0 | BW79: 0 | BX79: 0 | BY79: 0 | BZ79: 0 | CA79: 0 | CB79: 0 | CC79: 0 | CD79: 0 | CE79: 0 | CF79: 0 | CG79: 0 | CH79: 0 | CI79: 0 | CJ79: 0 | CK79: 0 | CL79: 0 | CM79: 0 | CN79: 0 | CO79: 0 | CP79: 0 | CQ79: 0 | CR79: 0 | CS79: 0 | CT79: 0 | CU79: 0 | CV79: 0 | CW79: 0 | CX79: 0 | CY79: 0 | CZ79: 0 | DA79: 0 | DB79: 0 | DC79: 0 | DD79: 0 | DE79: 0 | DF79: 0 | DG79: 0 | DH79: 0
A80: incept | B80: InceptionNet | C80: vm256 | D80: 256 | E80: tinyNAS | F80: PatchTS | G80: needTS_valid | H80: 0 | L80: 0 | M80: 0 | N80: 0 | O80: 0 | P80: 0 | Q80: 0 | R80: 0 | S80: 0 | T80: 0 | U80: 0 | V80: 0 | W80: 0 | X80: 0 | Y80: 0 | Z80: 0 | AA80: 0 | AB80: 0 | AC80: 0 | AD80: 0 | AE80: 0 | AF80: 0 | AG80: 0 | AH80: 0 | AI80: 0 | AJ80: 0 | AK80: 0 | AL80: 0 | AM80: 0 | AN80: 0 | AO80: 0 | AP80: 0 | AQ80: 0 | AR80: 0 | AS80: 0 | AT80: 0 | AU80: 0 | AV80: 0 | AW80: 0 | AX80: 0 | AY80: 0 | AZ80: 0 | BA80: 0 | BB80: 0 | BC80: 0 | BD80: 0 | BE80: 0 | BF80: 0 | BG80: 0 | BH80: 0 | BI80: 0 | BJ80: 0 | BK80: 0 | BL80: 0 | BM80: 0 | BN80: 0 | BO80: 0 | BP80: 0 | BQ80: 0 | BR80: 0 | BS80: 0 | BT80: 0 | BU80: 0 | BV80: 0 | BW80: 0 | BX80: 0 | BY80: 0 | BZ80: 0 | CA80: 0 | CB80: 0 | CC80: 0 | CD80: 0 | CE80: 0 | CF80: 0 | CG80: 0 | CH80: 0 | CI80: 0 | CJ80: 0 | CK80: 0 | CL80: 0 | CM80: 0 | CN80: 0 | CO80: 0 | CP80: 0 | CQ80: 0 | CR80: 0 | CS80: 0 | CT80: 0 | CU80: 0 | CV80: 0 | CW80: 0 | CX80: 0 | CY80: 0 | CZ80: 0 | DA80: 0 | DB80: 0 | DC80: 0 | DD80: 0 | DE80: 0 | DF80: 0 | DG80: 0 | DH80: 0
A81: incept | B81: InceptionNet | C81: vm256 | D81: 256 | E81: tinyNAS | F81: PatchTS | G81: needTS_invalid | H81: 981 | I81: 0 | J81: 0 | K81: 0 | L81: 981 | M81: 0 | N81: 0 | O81: 0 | P81: 0 | Q81: 0 | R81: 0 | S81: 0 | T81: 0 | U81: 0 | V81: 0 | W81: 0 | X81: 0 | Y81: 0 | Z81: 0 | AA81: 0 | AB81: 0 | AC81: 0 | AD81: 0 | AE81: 0 | AF81: 0 | AG81: 0 | AH81: 0 | AI81: 0 | AJ81: 0 | AK81: 0 | AL81: 0 | AM81: 0 | AN81: 0 | AO81: 0 | AP81: 0 | AQ81: 0 | AR81: 0 | AS81: 0 | AT81: 0 | AU81: 0 | AV81: 0 | AW81: 0 | AX81: 0 | AY81: 0 | AZ81: 0 | BA81: 0 | BB81: 0 | BC81: 0 | BD81: 0 | BE81: 0 | BF81: 0 | BG81: 0 | BH81: 0 | BI81: 0 | BJ81: 0 | BK81: 0 | BL81: 0 | BM81: 0 | BN81: 0 | BO81: 0 | BP81: 0 | BQ81: 0 | BR81: 0 | BS81: 0 | BT81: 0 | BU81: 0 | BV81: 0 | BW81: 0 | BX81: 0 | BY81: 0 | BZ81: 0 | CA81: 0 | CB81: 0 | CC81: 0 | CD81: 0 | CE81: 0 | CF81: 0 | CG81: 0 | CH81: 0 | CI81: 0 | CJ81: 0 | CK81: 0 | CL81: 0 | CM81: 0 | CN81: 0 | CO81: 0 | CP81: 0 | CQ81: 0 | CR81: 0 | CS81: 0 | CT81: 0 | CU81: 0 | CV81: 0 | CW81: 0 | CX81: 0 | CY81: 0 | CZ81: 0 | DA81: 0 | DB81: 0 | DC81: 0 | DD81: 0 | DE81: 0 | DF81: 0 | DG81: 0 | DH81: 0
